Workbook
Name Frage: [1]Basis!$I$2:$I$34
Name FranciscoMárquez: #REF!
Name FranciscoMárquez: #REF!
Name FranciscoMárquez: 'OEE FT EMPAQUE'!#REF!
Name FranciscoMárquez: 'OEE FT LEAKTEST'!#REF!
Name FranciscoMárquez: 'OEE FT LIM M Y S'!#REF!
Name FranciscoMárquez: 'OEE FT PRENSA'!#REF!
Name FranciscoMárquez: #REF!
Name FranciscoMárquez: #REF!
Name FranciscoMárquez: #REF!
Name NativeTimeline_FECHA: #N/A
Name Slicer_Años1: #N/A
Name wirksam: [1]Basis!$G$2:$G$3

Sheet OEE FT LIM M Y S
C1: FECHA | D1: TIEMPOS CAIDOS | G1: DISPONIBILIDAD | L1: RENDIMIENTO | P1: CALIDAD | AG1: OEE
A2: REF VLOOK UP | B2: turno | C2: FECHA | D2: SET UP | E2: PROCESO | F2: MTTO OTROS | G2: TIEMPO EXTRA | H2: TIEMPO CALCULADO | I2: TIEMPO PLANIFICADO | J2: TIEMPO OPERATIVO | K2: RESULTADO | L2: PIEZAS PRODUCIDAS | M2: ESTANDAR | N2: MIN X HORAS | O2: RESULTADO | P2: PIEZAS BUENAS | Q2: PIEZAS PRODUCIDAS | R2: Rebaba de ventana | S2: Limado excesivo | T2: PUNTO | U2: Caidas al piso | V2: Piezas con fuga | W2: Piezas con golpes | X2: Soldadura sañada | Y2: daño limado manual | Z2: Otro | AA2: Ajsutes de Ingenieria | AB2: Ajustes de MTTO | AC2: Week Number | AD2: QA TOTAL | AE2: SCRAP | AF2: RESULTADO | AG2: RESULTADO
B3: 1 | C3: 44621 | H3: 540 | I3: 540 | J3: =I3-D3-E3-F3 -> 540 | K3: =IFERROR(J3/I3,"") -> 1 | L3: 2722 | M3: 300 | N3: 60 | O3: =IFERROR(((L3/M3)*N3/J3),"") -> 1.0081481 | P3: =L3-AE3 -> 2717 | Q3: =L3 -> 2722 | S3: 3 | U3: 2 | AC3: =WEEKNUM(C3) -> 10 | AD3: =AB3+AA3+Z3+Y3+X3+W3+V3+U3+T3+S3+R3 -> 5 | AE3: =AD3 -> 5 | AF3: =IFERROR(P3/Q3,"") -> 0.99816312 | AG3: =IFERROR(K3*O3*AF3,"") -> 1.0062963
B4: 1 | C4: 44622 | F4: 7 | H4: 360 | I4: 360 | J4: =I4-D4-E4-F4 -> 353 | K4: =IFERROR(J4/I4,"") -> 0.98055556 | L4: 1737 | M4: 300 | N4: 60 | O4: =IFERROR(((L4/M4)*N4/J4),"") -> 0.98413598 | P4: 1731 | Q4: 1737 | U4: 4 | W4: 2 | AE4: =AD4 -> 0 | AF4: =IFERROR(P4/Q4,"") -> 0.99654577 | AG4: =IFERROR(K4*O4*AF4,"") -> 0.96166667
B5: 1 | C5: 44623 | H5: 400 | I5: 400 | J5: =I5-D5-E5-F5 -> 400 | K5: =IFERROR(J5/I5,"") -> 1 | L5: 1951 | M5: 300 | N5: 60 | O5: =IFERROR(((L5/M5)*N5/J5),"") -> 0.9755 | P5: 1949 | Q5: 1949 | Z5: 2 | AE5: =AD5 -> 0 | AF5: =IFERROR(P5/Q5,"") -> 1 | AG5: =IFERROR(K5*O5*AF5,"") -> 0.9755
B6: 1 | C6: 44624 | H6: 360 | I6: 360 | J6: =I6-D6-E6-F6 -> 360 | K6: =IFERROR(J6/I6,"") -> 1 | L6: 1566 | M6: 300 | N6: 60 | O6: =IFERROR(((L6/M6)*N6/J6),"") -> 0.87 | P6: 1564 | Q6: 1566 | U6: 1 | W6: 1 | AE6: =AD6 -> 0 | AF6: =IFERROR(P6/Q6,"") -> 0.99872286 | AG6: =IFERROR(K6*O6*AF6,"") -> 0.86888889
B7: 1 | C7: 44627 | E7: 37 | F7: 20 | H7: 410 | I7: 410 | J7: =I7-D7-E7-F7 -> 353 | K7: =IFERROR(J7/I7,"") -> 0.86097561 | L7: 1754 | M7: 300 | N7: 60 | O7: =IFERROR(((L7/M7)*N7/J7),"") -> 0.99376771 | P7: 1752 | Q7: 1754 | W7: 2 | AE7: =AD7 -> 0 | AF7: =IFERROR(P7/Q7,"") -> 0.99885975 | AG7: =IFERROR(K7*O7*AF7,"") -> 0.85463415
B8: 1 | C8: 44628 | D8: 40 | E8: 75 | F8: 27 | H8: 480 | I8: 480 | J8: =I8-D8-E8-F8 -> 338 | K8: =IFERROR(J8/I8,"") -> 0.70416667 | L8: 1731 | M8: 300 | N8: 60 | O8: =IFERROR(((L8/M8)*N8/J8),"") -> 1.0242604 | P8: 1726 | Q8: 1731 | Y8: 5 | AE8: =AD8 -> 0 | AF8: =IFERROR(P8/Q8,"") -> 0.9971115 | AG8: =IFERROR(K8*O8*AF8,"") -> 0.71916667
B9: 1 | C9: 44629 | E9: 40 | H9: 510 | I9: 510 | J9: =I9-D9-E9-F9 -> 470 | K9: =IFERROR(J9/I9,"") -> 0.92156863 | L9: 2412 | M9: 300 | N9: 60 | O9: =IFERROR(((L9/M9)*N9/J9),"") -> 1.026383 | P9: 2411 | Q9: 2412 | W9: 1 | AE9: =AD9 -> 0 | AF9: =IFERROR(P9/Q9,"") -> 0.99958541 | AG9: =IFERROR(K9*O9*AF9,"") -> 0.9454902
B10: 1 | C10: 44630 | E10: 130 | H10: 510 | I10: 510 | J10: =I10-D10-E10-F10 -> 380 | K10: =IFERROR(J10/I10,"") -> 0.74509804 | L10: 1757 | M10: 300 | N10: 60 | O10: =IFERROR(((L10/M10)*N10/J10),"") -> 0.92473684 | P10: 1755 | Q10: 1757 | W10: 1 | Z10: 1 | AE10: =AD10 -> 0 | AF10: =IFERROR(P10/Q10,"") -> 0.9988617 | AG10: =IFERROR(K10*O10*AF10,"") -> 0.68823529
B11: 1 | C11: 44631 | E11: 95 | F11: 30 | H11: 510 | I11: 510 | J11: =I11-D11-E11-F11 -> 385 | K11: =IFERROR(J11/I11,"") -> 0.75490196 | L11: 1867 | M11: 300 | N11: 60 | O11: =IFERROR(((L11/M11)*N11/J11),"") -> 0.96987013 | P11: 1862 | Q11: 1867 | T11: 1 | U11: 1 | W11: 2 | Z11: 1 | AE11: =AD11 -> 0 | AF11: =IFERROR(P11/Q11,"") -> 0.99732191
B12: 1 | J12: =I12-D12-E12-F12 -> 0 | K12: =IFERROR(J12/I12,"") | AF12: =IFERROR(P12/Q12,"")
B13: 1 | J13: =I13-D13-E13-F13 -> 0 | K13: =IFERROR(J13/I13,"")
B14: 1 | J14: =I14-D14-E14-F14 -> 0 | K14: =IFERROR(J14/I14,"")
B15: 1 | J15: =I15-D15-E15-F15 -> 0 | K15: =IFERROR(J15/I15,"")
B16: 1
B17: 1
B18: 1
B19: 1
B20: 1
B21: 1
B22: 1
B23: 1
B24: 1
B25: 1
B26: 1
B27: 1
... B42: 1
I222: =H222+G222 -> 0 | J222: =I222-D222-E222-F222 -> 0 | K222: =IFERROR(J222/I222,"") | M222: 300 | N222: 60 | O222: =IFERROR(((L222/M222)*N222/J222),"") | P222: =L222-AE222 -> 0 | Q222: =L222 -> 0 | AG222: =IFERROR(K222*O222*AF222,"")
I223: =H223+G223 -> 0 | J223: =I223-D223-E223-F223 -> 0 | K223: =IFERROR(J223/I223,"") | M223: 300 | N223: 60 | O223: =IFERROR(((L223/M223)*N223/J223),"") | P223: =L223-AE223 -> 0 | Q223: =L223 -> 0 | AG223: =IFERROR(K223*O223*AF223,"")
I224: =H224+G224 -> 0 | J224: =I224-D224-E224-F224 -> 0 | K224: =IFERROR(J224/I224,"") | M224: 300 | N224: 60 | O224: =IFERROR(((L224/M224)*N224/J224),"") | P224: =L224-AE224 -> 0 | Q224: =L224 -> 0 | AG224: =IFERROR(K224*O224*AF224,"")
I225: =H225+G225 -> 0 | J225: =I225-D225-E225-F225 -> 0 | K225: =IFERROR(J225/I225,"") | M225: 300 | N225: 60 | O225: =IFERROR(((L225/M225)*N225/J225),"") | P225: =L225-AE225 -> 0 | Q225: =L225 -> 0 | AG225: =IFERROR(K225*O225*AF225,"")
I226: =H226+G226 -> 0 | J226: =I226-D226-E226-F226 -> 0 | K226: =IFERROR(J226/I226,"") | M226: 300 | N226: 60 | O226: =IFERROR(((L226/M226)*N226/J226),"") | P226: =L226-AE226 -> 0 | Q226: =L226 -> 0 | AG226: =IFERROR(K226*O226*AF226,"")
I227: =H227+G227 -> 0 | J227: =I227-D227-E227-F227 -> 0 | K227: =IFERROR(J227/I227,"") | M227: 300 | N227: 60 | O227: =IFERROR(((L227/M227)*N227/J227),"") | P227: =L227-AE227 -> 0 | Q227: =L227 -> 0 | AG227: =IFERROR(K227*O227*AF227,"")
I228: =H228+G228 -> 0 | J228: =I228-D228-E228-F228 -> 0 | K228: =IFERROR(J228/I228,"") | M228: 300 | N228: 60 | O228: =IFERROR(((L228/M228)*N228/J228),"") | P228: =L228-AE228 -> 0 | Q228: =L228 -> 0 | AG228: =IFERROR(K228*O228*AF228,"")
I229: =H229+G229 -> 0 | J229: =I229-D229-E229-F229 -> 0 | K229: =IFERROR(J229/I229,"") | M229: 300 | N229: 60 | O229: =IFERROR(((L229/M229)*N229/J229),"") | P229: =L229-AE229 -> 0 | Q229: =L229 -> 0 | AG229: =IFERROR(K229*O229*AF229,"")
I230: =H230+G230 -> 0 | J230: =I230-D230-E230-F230 -> 0 | K230: =IFERROR(J230/I230,"") | M230: 300 | N230: 60 | O230: =IFERROR(((L230/M230)*N230/J230),"") | P230: =L230-AE230 -> 0 | Q230: =L230 -> 0 | AG230: =IFERROR(K230*O230*AF230,"")
I231: =H231+G231 -> 0 | J231: =I231-D231-E231-F231 -> 0 | K231: =IFERROR(J231/I231,"") | M231: 300 | N231: 60 | O231: =IFERROR(((L231/M231)*N231/J231),"") | P231: =L231-AE231 -> 0 | Q231: =L231 -> 0 | AG231: =IFERROR(K231*O231*AF231,"")
I232: =H232+G232 -> 0 | J232: =I232-D232-E232-F232 -> 0 | K232: =IFERROR(J232/I232,"") | M232: 300 | N232: 60 | O232: =IFERROR(((L232/M232)*N232/J232),"") | P232: =L232-AE232 -> 0 | Q232: =L232 -> 0 | AG232: =IFERROR(K232*O232*AF232,"")
I233: =H233+G233 -> 0 | J233: =I233-D233-E233-F233 -> 0 | K233: =IFERROR(J233/I233,"") | M233: 300 | N233: 60 | O233: =IFERROR(((L233/M233)*N233/J233),"") | P233: =L233-AE233 -> 0 | Q233: =L233 -> 0 | AG233: =IFERROR(K233*O233*AF233,"")
...

Sheet OEE FT LEAKTEST
C1: FECHA | D1: TIEMPOS CAIDOS | G1: DISPONIBILIDAD | L1: RENDIMIENTO | P1: CALIDAD | AQ1: OEE
A2: REF VLOOK UP | B2: turno | C2: FECHA | D2: SET UP | E2: PROCESO | F2: MTTO OTROS | G2: TIEMPO EXTRA | H2: TIEMPO CALCULADO | I2: TIEMPO PLANIFICADO | J2: TIEMPO OPERATIVO | K2: RESULTADO | L2: PIEZAS PRODUCIDAS | M2: ESTANDAR | N2: MIN X HORAS | O2: RESULTADO | P2: PIEZAS BUENAS | Q2: PIEZAS PRODUCIDAS | R2: Punto | S2: Limado excesivo | T2: Dañada por navaja | U2: Marcas de rodillo | V2: Labio levantado | W2: piezas largas | X2: Piezas cortas | Y2: Caidas al piso | Z2: Piezas con fuga | AA2: Piezas con golpes | AB2: Soldadura sañada | AC2: Doble grabado | AD2: Wavy | AE2: Mal grabado | AF2: Otro | AG2: Ajsutes de Ingenieria | AH2: Ajustes de MTTO | AI2: Soldadura desalineada | AJ2: Ondulacion | AK2: Hundida | AL2: Piezas largas | AM2: QA TOTAL | AN2: Week Number | AO2: SCRAP | AP2: RESULTADO | AQ2: RESULTADO
B3: 1 | C3: 44621 | E3: 17 | H3: 460 | I3: =H3+G3 -> 460 | J3: =I3-D3-E3-F3 -> 443 | K3: =IFERROR(J3/I3,"") -> 0.96304348 | L3: 1979 | M3: 300 | N3: 60 | O3: =IFERROR(((L3/M3)*N3/J3),"") -> 0.89345372 | P3: =L3-AO3 -> 1971 | Q3: =L3 -> 1979 | S3: 5 | AA3: 1 | AF3: 2 | AM3: =AL3+AK3+AJ3+AI3+AH3+AG3+AF3+AE3+AD3+AC3+AB3+AA3+Z3+Y3+X3+W3+V3+U3+T3+S3+R3 -> 8 | AN3: =WEEKNUM(C3) -> 10 | AO3: =SUM(R3:AL3) -> 8 | AP3: =IFERROR(P3/Q3,"") -> 0.99595755 | AQ3: =IFERROR(K3*O3*AP3,"") -> 0.85695652
B4: 1 | C4: 44622 | D4: 15 | E4: 15 | F4: 16 | H4: 480 | I4: 480 | J4: =I4-D4-E4-F4 -> 434 | K4: =IFERROR(J4/I4,"") -> 0.90416667 | L4: 2131 | M4: 300 | N4: 60 | O4: =IFERROR(((L4/M4)*N4/J4),"") -> 0.98202765 | P4: 2126 | Q4: 2131 | Y4: 1 | AA4: 2 | AF4: 2 | AO4: =SUM(R4:AL4) -> 5 | AP4: =IFERROR(P4/Q4,"") -> 0.99765368 | AQ4: =IFERROR(K4*O4*AP4,"") -> 0.88583333
B5: 1 | C5: 44623 | D5: 17 | E5: 18 | F5: 4 | H5: 490 | I5: 490 | J5: =I5-D5-E5-F5 -> 451 | K5: =IFERROR(J5/I5,"") -> 0.92040816 | L5: 2257 | M5: 300 | N5: 60 | O5: =IFERROR(((L5/M5)*N5/J5),"") -> 1.0008869 | P5: 2247 | Q5: 2257 | R5: 1 | U5: 9 | AA5: 1 | AF5: 1 | AO5: =SUM(R5:AL5) -> 12 | AP5: =IFERROR(P5/Q5,"") -> 0.99556934 | AQ5: =IFERROR(K5*O5*AP5,"") -> 0.91714286
B6: 1 | C6: 44624 | D6: 15 | E6: 7 | H6: 400 | I6: 400 | J6: =I6-D6-E6-F6 -> 378 | K6: =IFERROR(J6/I6,"") -> 0.945 | L6: 1615 | M6: 300 | N6: 60 | O6: =IFERROR(((L6/M6)*N6/J6),"") -> 0.85449735 | P6: 1611 | Q6: 1615 | AF6: 4 | AO6: =SUM(R6:AL6) -> 4 | AP6: =IFERROR(P6/Q6,"") -> 0.99752322 | AQ6: =IFERROR(K6*O6*AP6,"") -> 0.8055
B7: 1 | C7: 44627 | D7: 19 | E7: 34 | H7: 400 | I7: 400 | J7: =I7-D7-E7-F7 -> 347 | K7: =IFERROR(J7/I7,"") -> 0.8675 | L7: 1696 | M7: 300 | N7: 60 | O7: =IFERROR(((L7/M7)*N7/J7),"") -> 0.97752161 | P7: 1675 | Q7: 1696 | AA7: 1 | AC7: 2 | AF7: 18 | AO7: =SUM(R7:AL7) -> 21 | AP7: =IFERROR(P7/Q7,"") -> 0.98761792 | AQ7: =IFERROR(K7*O7*AP7,"") -> 0.8375
B8: 1 | C8: 44628 | D8: 38 | E8: 59 | H8: 480 | I8: 480 | J8: =I8-D8-E8-F8 -> 383 | K8: =IFERROR(J8/I8,"") -> 0.79791667 | L8: 1901 | M8: 300 | N8: 60 | O8: =IFERROR(((L8/M8)*N8/J8),"") -> 0.9926893 | P8: 1896 | Q8: 1901 | AO8: =SUM(R8:AL8) -> 0 | AP8: =IFERROR(P8/Q8,"") -> 0.99736981 | AQ8: =IFERROR(K8*O8*AP8,"") -> 0.79
B9: 1 | C9: 44629 | E9: 33 | H9: 480 | I9: 480 | J9: =I9-D9-E9-F9 -> 447 | K9: =IFERROR(J9/I9,"") -> 0.93125 | L9: 2056 | M9: 300 | N9: 60 | O9: =IFERROR(((L9/M9)*N9/J9),"") -> 0.91991051 | P9: 2051 | Q9: 2056 | AA9: 3 | AC9: 1 | AD9: 1 | AO9: =SUM(R9:AL9) -> 5 | AP9: =IFERROR(P9/Q9,"") -> 0.99756809 | AQ9: =IFERROR(K9*O9*AP9,"") -> 0.85458333
B10: 1 | C10: 44630 | D10: 10 | E10: 42 | H10: 480 | I10: 480 | J10: =I10-D10-E10-F10 -> 428 | K10: =IFERROR(J10/I10,"") -> 0.89166667 | L10: 2112 | M10: 300 | N10: 60 | O10: =IFERROR(((L10/M10)*N10/J10),"") -> 0.98691589 | P10: 2110 | Q10: 2112 | Y10: 2 | AO10: =SUM(R10:AL10) -> 2 | AP10: =IFERROR(P10/Q10,"") -> 0.99905303 | AQ10: =IFERROR(K10*O10*AP10,"") -> 0.87916667
B11: 1 | C11: 44631 | D11: 10 | E11: 34 | H11: 480 | I11: 480 | J11: =I11-D11-E11-F11 -> 436 | K11: =IFERROR(J11/I11,"") -> 0.90833333 | L11: 1931 | M11: 300 | N11: 60 | O11: =IFERROR(((L11/M11)*N11/J11),"") -> 0.88577982 | P11: 1927 | Q11: 1931 | X11: 3 | AA11: 1 | AO11: =SUM(R11:AL11) -> 4 | AP11: =IFERROR(P11/Q11,"") -> 0.99792853 | AQ11: =IFERROR(K11*O11*AP11,"") -> 0.80291667
B12: 1 | J12: =I12-D12-E12-F12 -> 0 | K12: =IFERROR(J12/I12,"") | AQ12: =IFERROR(K12*O12*AP12,"")
B13: 1 | J13: =I13-D13-E13-F13 -> 0 | K13: =IFERROR(J13/I13,"") | AQ13: =IFERROR(K13*O13*AP13,"")
B14: 1 | J14: =I14-D14-E14-F14 -> 0 | K14: =IFERROR(J14/I14,"") | AQ14: =IFERROR(K14*O14*AP14,"")
B15: 1 | J15: =I15-D15-E15-F15 -> 0 | K15: =IFERROR(J15/I15,"") | AQ15: =IFERROR(K15*O15*AP15,"")
B16: 1 | J16: =I16-D16-E16-F16 -> 0 | K16: =IFERROR(J16/I16,"") | AQ16: =IFERROR(K16*O16*AP16,"")
B17: 1 | AQ17: =IFERROR(K17*O17*AP17,"") -> 0
B18: 1 | AQ18: =IFERROR(K18*O18*AP18,"") -> 0
B19: 1 | AQ19: =IFERROR(K19*O19*AP19,"") -> 0
B20: 1 | AQ20: =IFERROR(K20*O20*AP20,"") -> 0
B21: 1 | AQ21: =IFERROR(K21*O21*AP21,"") -> 0
B22: 1 | AQ22: =IFERROR(K22*O22*AP22,"") -> 0
B23: 1 | AQ23: =IFERROR(K23*O23*AP23,"") -> 0
B24: 1 | AQ24: =IFERROR(K24*O24*AP24,"") -> 0
B25: 1 | AQ25: =IFERROR(K25*O25*AP25,"") -> 0
B26: 1 | AQ26: =IFERROR(K26*O26*AP26,"") -> 0
B27: 1 | AQ27: =IFERROR(K27*O27*AP27,"") -> 0
B28: 1 | AQ28: =IFERROR(K28*O28*AP28,"") -> 0
... B41: 1 | AQ41: =IFERROR(K41*O41*AP41,"") -> 0
AQ42: =IFERROR(K42*O42*AP42,"") -> 0
AQ43: =IFERROR(K43*O43*AP43,"") -> 0
AQ44: =IFERROR(K44*O44*AP44,"") -> 0
AQ45: =IFERROR(K45*O45*AP45,"") -> 0
AQ46: =IFERROR(K46*O46*AP46,"") -> 0
AQ47: =IFERROR(K47*O47*AP47,"") -> 0
AQ48: =IFERROR(K48*O48*AP48,"") -> 0
AQ49: =IFERROR(K49*O49*AP49,"") -> 0
AQ50: =IFERROR(K50*O50*AP50,"") -> 0
AQ51: =IFERROR(K51*O51*AP51,"") -> 0
AQ52: =IFERROR(K52*O52*AP52,"") -> 0
...

Sheet OEE FT PRENSA
D1: TIEMPOS CAIDOS | G1: DISPONIBILIDAD | L1: RENDIMIENTO | P1: CALIDAD | AG1: OEE
A2: REF VLOOK UP | B2: TURNO | C2: FECHA | D2: CALIDAD | E2: PROCESO | F2: MTTO OTROS | G2: TIEMPO EXTRA | H2: TIEMPO CALCULADO | I2: TIEMPO PLANIFICADO | J2: TIEMPO OPERATIVO | K2: RESULTADO | L2: PIEZAS PRODUCIDAS | M2: ESTANDAR | N2: MIN X HORAS | O2: RESULTADO | P2: PIEZAS BUENAS | Q2: PIEZAS PRODUCIDAS | R2: Prensa | S2: Rebaba de ventana | T2: Punto | U2: Falla de la maquina | V2: caida al piso | W2: Piezas con golpes | X2: Otro | Y2: Ajsutes de Ingenieria | Z2: Ajustes de MTTO | AA2: Labio levantado | AB2: Caidas al piso | AC2: QA TOTAL | AD2: Week Number | AE2: SCRAP | AF2: RESULTADO | AG2: RESULTADO
B3: 1 | C3: 44621 | H3: 200 | I3: 200 | J3: =H3-F3-E3-D3 -> 200 | K3: =IFERROR(J3/I3,"-") -> 1 | L3: 915 | M3: 300 | N3: 60 | O3: =IFERROR(((L3/M3)*N3/J3),"-") -> 0.915 | P3: 913 | Q3: 915 | T3: 3 | W3: 3 | AD3: =WEEKNUM(C3) -> 10 | AE3: =SUM(R3+S3+T3+U3+V3+W3+X3+Y3+Z3+AA3+AB3) -> 6 | AF3: =IFERROR(P3/Q3,"-") -> 0.99781421 | AG3: =IFERROR(K3*O3*AF3,"-") -> 0.913
B4: 1 | C4: 44622 | D4: 45 | F4: 10 | H4: 480 | I4: 480 | J4: =H4-F4-E4-D4 -> 425 | K4: =IFERROR(J4/I4,"-") -> 0.88541667 | L4: 2019 | M4: 300 | N4: 60 | O4: =IFERROR(((L4/M4)*N4/J4),"-") -> 0.95011765 | P4: 2014 | Q4: 2019 | T4: 2 | W4: 3 | AE4: =SUM(R4+S4+T4+U4+V4+W4+X4+Y4+Z4+AA4+AB4) -> 5 | AF4: =IFERROR(P4/Q4,"-") -> 0.99752353 | AG4: =IFERROR(K4*O4*AF4,"-") -> 0.83916667
B5: 1 | C5: 44623 | D5: 45 | H5: 500 | I5: 500 | J5: =H5-F5-E5-D5 -> 455 | K5: =IFERROR(J5/I5,"-") -> 0.91 | L5: 2237 | M5: 300 | N5: 60 | O5: =IFERROR(((L5/M5)*N5/J5),"-") -> 0.9832967 | P5: 2226 | Q5: 2237 | T5: 6 | W5: 5 | AE5: =SUM(R5+S5+T5+U5+V5+W5+X5+Y5+Z5+AA5+AB5) -> 11 | AF5: =IFERROR(P5/Q5,"-") -> 0.9950827 | AG5: =IFERROR(K5*O5*AF5,"-") -> 0.8904
B6: 1 | C6: 44624 | E6: 60 | H6: 340 | I6: 340 | J6: =H6-F6-E6-D6 -> 280 | K6: =IFERROR(J6/I6,"-") -> 0.82352941 | L6: 1167 | M6: 300 | N6: 60 | O6: =IFERROR(((L6/M6)*N6/J6),"-") -> 0.83357143 | P6: 1166 | Q6: 1167 | T6: 1 | AE6: =SUM(R6+S6+T6+U6+V6+W6+X6+Y6+Z6+AA6+AB6) -> 1 | AF6: =IFERROR(P6/Q6,"-") -> 0.9991431 | AG6: =IFERROR(K6*O6*AF6,"-") -> 0.68588235
B7: 1 | C7: 44627 | E7: 37 | H7: 450 | I7: 450 | J7: =H7-F7-E7-D7 -> 413 | K7: =IFERROR(J7/I7,"-") -> 0.91777778 | L7: 2086 | M7: 300 | N7: 60 | O7: =IFERROR(((L7/M7)*N7/J7),"-") -> 1.0101695 | P7: 2082 | Q7: 2086 | AE7: =SUM(R7+S7+T7+U7+V7+W7+X7+Y7+Z7+AA7+AB7) -> 0 | AF7: =IFERROR(P7/Q7,"-") -> 0.99808245 | AG7: =IFERROR(K7*O7*AF7,"-") -> 0.92533333
B8: 1 | C8: 44628 | D8: 50 | F8: 30 | H8: 480 | I8: 480 | J8: =H8-F8-E8-D8 -> 400 | K8: =IFERROR(J8/I8,"-") -> 0.83333333 | L8: 1908 | M8: 300 | N8: 60 | O8: =IFERROR(((L8/M8)*N8/J8),"-") -> 0.954 | P8: 1903 | Q8: 1908 | T8: 5 | AE8: =SUM(R8+S8+T8+U8+V8+W8+X8+Y8+Z8+AA8+AB8) -> 5 | AF8: =IFERROR(P8/Q8,"-") -> 0.99737945 | AG8: =IFERROR(K8*O8*AF8,"-") -> 0.79291667
B9: 1 | C9: 44629 | H9: 480 | I9: 480 | J9: =H9-F9-E9-D9 -> 480 | K9: =IFERROR(J9/I9,"-") -> 1 | L9: 2047 | M9: 300 | N9: 60 | O9: =IFERROR(((L9/M9)*N9/J9),"-") -> 0.85291667 | P9: 2044 | Q9: 2047 | T9: 1 | W9: 2 | AE9: =SUM(R9+S9+T9+U9+V9+W9+X9+Y9+Z9+AA9+AB9) -> 3 | AF9: =IFERROR(P9/Q9,"-") -> 0.99853444 | AG9: =IFERROR(K9*O9*AF9,"-") -> 0.85166667
B10: 1 | C10: 44630 | D10: 10 | E10: 40 | F10: 40 | H10: 510 | I10: 480 | J10: =H10-F10-E10-D10 -> 420 | K10: =IFERROR(J10/I10,"-") -> 0.875 | L10: 2128 | M10: 300 | N10: 60 | O10: =IFERROR(((L10/M10)*N10/J10),"-") -> 1.0133333 | P10: 2122 | Q10: 2128 | T10: 1 | V10: 1 | W10: 4 | AE10: =SUM(R10+S10+T10+U10+V10+W10+X10+Y10+Z10+AA10+AB10) -> 6 | AF10: =IFERROR(P10/Q10,"-") -> 0.99718045 | AG10: =IFERROR(K10*O10*AF10,"-") -> 0.88416667
B11: 1 | C11: 44631 | E11: 156 | H11: 480 | I11: 510 | J11: =H11-F11-E11-D11 -> 324 | K11: =IFERROR(J11/I11,"-") -> 0.63529412 | L11: 1621 | M11: 300 | N11: 60 | O11: =IFERROR(((L11/M11)*N11/J11),"-") -> 1.0006173 | P11: 1603 | Q11: 1621 | T11: 10 | W11: 8 | AE11: =SUM(R11+S11+T11+U11+V11+W11+X11+Y11+Z11+AA11+AB11) -> 18 | AF11: =IFERROR(P11/Q11,"-") -> 0.98889574 | AG11: =IFERROR(K11*O11*AF11,"-") -> 0.62862745
B12: 1 | J12: =H12-F12-E12-D12 -> 0 | K12: =IFERROR(J12/I12,"-") -> - | AE12: =SUM(R12+S12+T12+U12+V12+W12+X12+Y12+Z12+AA12+AB12) -> 0 | AF12: =IFERROR(P12/Q12,"-") -> - | AG12: =IFERROR(K12*O12*AF12,"-") -> -
B13: 1 | J13: =H13-F13-E13-D13 -> 0 | K13: =IFERROR(J13/I13,"-") -> - | AF13: =IFERROR(P13/Q13,"-") -> - | AG13: =IFERROR(K13*O13*AF13,"-") -> -
B14: 1
B15: 1
B16: 1
B17: 1
B18: 1
B19: 1
B20: 1
B21: 1
B22: 1
B23: 1
B24: 1
B25: 1
... B93: 1

Sheet OEE FT EMPAQUE
D1: TIEMPOS CAIDOS | G1: DISPONIBILIDAD | L1: RENDIMIENTO | P1: CALIDAD | AI1: OEE
A2: REF VLOOK UP | B2: TURNO | C2: FECHA | D2: CALIDAD | E2: PROCESO | F2: MTTO OTROS | G2: TIEMPO EXTRA | H2: TIEMPO CALCULADO | I2: TIEMPO PLANIFICADO | J2: TIEMPO OPERATIVO | K2: RESULTADO | L2: PIEZAS PRODUCIDAS | M2: ESTANDAR | N2: MIN X HORAS | O2: RESULTADO | P2: PIEZAS BUENAS | Q2: PIEZAS PRODUCIDAS | R2: Doble grabado | S2: Labio | T2: Wavy | U2: Mal estampado | V2: Punto | W2: Limado manual | X2: Prensa | Y2: Piezas con golpes | Z2: Otro | AA2: Dañada por navaja | AB2: limado excesivo | AC2: Marcas de rodillo | AD2: caida al piso | AE2: QA TOTAL | AF2: Week Number | AG2: SCRAP | AH2: RESULTADO | AI2: RESULTADO
B3: 1 | C3: 44621 | E3: 20 | H3: 360 | I3: =H3+G3 -> 360 | J3: =I3-F3-E3-D3 -> 340 | K3: =IFERROR(J3/I3,"-") -> 0.94444444 | L3: 1700 | M3: 300 | N3: 60 | O3: =IFERROR(((L3/M3)*N3/J3),"-") -> 1 | P3: 1700 | Q3: 1700 | R3: 2 | V3: 5 | Y3: 4 | Z3: 2 | AB3: 30 | AF3: =WEEKNUM(C3) -> 10 | AG3: =(R3+S3+T3+U3+V3+W3+X3+Y3+Z3+AA3+AB3+AC3+AD3) -> 43 | AH3: =IFERROR(P3/Q3,"-") -> 1 | AI3: =IFERROR(K3*O3*AH3,"-") -> 0.94444444
B4: 1 | C4: 44622 | E4: 20 | H4: 500 | I4: 500 | J4: =I4-F4-E4-D4 -> 480 | K4: =IFERROR(J4/I4,"-") -> 0.96 | L4: 2400 | M4: 300 | N4: 60 | O4: =IFERROR(((L4/M4)*N4/J4),"-") -> 1 | P4: 2400 | Q4: 2400 | W4: 51 | Y4: 3 | AB4: 16 | AG4: =(R4+S4+T4+U4+V4+W4+X4+Y4+Z4+AA4+AB4+AC4+AD4) -> 70 | AH4: =IFERROR(P4/Q4,"-") -> 1 | AI4: =IFERROR(K4*O4*AH4,"-") -> 0.96
B5: 1 | C5: 44623 | H5: 420 | I5: 420 | J5: =I5-F5-E5-D5 -> 420 | K5: =IFERROR(J5/I5,"-") -> 1 | L5: 2100 | M5: 300 | N5: 60 | O5: =IFERROR(((L5/M5)*N5/J5),"-") -> 1 | P5: 2100 | Q5: 2100 | R5: 1 | W5: 31 | Y5: 8 | AB5: 2 | AG5: =(R5+S5+T5+U5+V5+W5+X5+Y5+Z5+AA5+AB5+AC5+AD5) -> 42 | AH5: =IFERROR(P5/Q5,"-") -> 1 | AI5: =IFERROR(K5*O5*AH5,"-") -> 1
B6: 1 | C6: 44624 | H6: 480 | I6: 480 | J6: =I6-F6-E6-D6 -> 480 | K6: =IFERROR(J6/I6,"-") -> 1 | L6: 2400 | M6: 300 | N6: 60 | O6: =IFERROR(((L6/M6)*N6/J6),"-") -> 1 | P6: 2400 | Q6: 2400 | W6: 9 | Z6: 1 | AB6: 2 | AG6: =(R6+S6+T6+U6+V6+W6+X6+Y6+Z6+AA6+AB6+AC6+AD6) -> 12 | AH6: =IFERROR(P6/Q6,"-") -> 1 | AI6: =IFERROR(K6*O6*AH6,"-") -> 1
B7: 1 | C7: 44627 | H7: 360 | I7: 360 | J7: =I7-F7-E7-D7 -> 360 | K7: =IFERROR(J7/I7,"-") -> 1 | L7: 1700 | M7: 300 | N7: 60 | O7: =IFERROR(((L7/M7)*N7/J7),"-") -> 0.94444444 | P7: 1700 | Q7: 1700 | Z7: 2 | AH7: =IFERROR(P7/Q7,"-") -> 1 | AI7: =IFERROR(K7*O7*AH7,"-") -> 0.94444444
B8: 1 | C8: 44628 | H8: 420 | I8: 420 | J8: =I8-F8-E8-D8 -> 420 | K8: =IFERROR(J8/I8,"-") -> 1 | L8: 2100 | M8: 300 | N8: 60 | O8: =IFERROR(((L8/M8)*N8/J8),"-") -> 1 | P8: 2100 | Q8: 2100 | AH8: =IFERROR(P8/Q8,"-") -> 1 | AI8: =IFERROR(K8*O8*AH8,"-") -> 1
B9: 1 | C9: 44629 | H9: 150 | I9: 150 | J9: =I9-F9-E9-D9 -> 150 | K9: =IFERROR(J9/I9,"-") -> 1 | L9: 700 | M9: 300 | N9: 60 | O9: =IFERROR(((L9/M9)*N9/J9),"-") -> 0.93333333 | P9: 700 | Q9: 700 | AH9: =IFERROR(P9/Q9,"-") -> 1 | AI9: =IFERROR(K9*O9*AH9,"-") -> 0.93333333
B10: 1 | C10: 44630 | H10: 480 | I10: 480 | J10: =I10-F10-E10-D10 -> 480 | K10: =IFERROR(J10/I10,"-") -> 1 | L10: 2400 | M10: 300 | N10: 60 | O10: =IFERROR(((L10/M10)*N10/J10),"-") -> 1 | P10: 2400 | Q10: 2400 | AH10: =IFERROR(P10/Q10,"-") -> 1 | AI10: =IFERROR(K10*O10*AH10,"-") -> 1
B11: 1 | C11: 44631 | H11: 240 | I11: 240 | J11: =I11-F11-E11-D11 -> 240 | K11: =IFERROR(J11/I11,"-") -> 1 | L11: 1200 | M11: 300 | N11: 60 | O11: =IFERROR(((L11/M11)*N11/J11),"-") -> 1 | P11: 1200 | Q11: 1200 | AH11: =IFERROR(P11/Q11,"-") -> 1 | AI11: =IFERROR(K11*O11*AH11,"-") -> 1
B12: 1
B13: 1
B14: 1
B15: 1
B16: 1
B17: 1
B18: 1
B19: 1
B20: 1
B21: 1
B22: 1
B23: 1
... B30: 1

Sheet GRAFICA FORMADORA
A1: Día | B1: OEE
A2: 1 | B2: 0.82652406
A3: 4 | B3: 0.9
A4: 5 | B4: 0.08855615
A5: 7 | B5: 0.46545455
A6: 7 | B6: 0.16941176
A7: 9 | B7: 0.66762588
A8: 10 | B8: 0.31871658
A9: 10 | B9: 0.37775401
A10: 11 | B10: 0.45048128
A11: 11 | B11: 0.77901159
A12: 12 | B12: 0.38588235
A13: 14 | B13: 0.11324675
... A32: 43497 | B32: 0.9725
A34: TOTAL | B34: =IFERROR(AVERAGE(B2:B23),"") -> 0.51025644

Sheet Hoja1
A1: Etiquetas de fila | B1: Suma de RESULTADO DISPONIBILIDAD | C1: Suma de RESULTADO RENDIMIENTO | D1: Suma de RESULTADO CALIDAD
A2: 43467 | B2: 0.85882353 | C2: 0.96239103 | D2: 1
A3: 43468
A4: 43469 | B4: 0.45531915 | C4: 1.011045 | D4: 0.89915966
A5: 43470 | B5: 0.11058824 | C5: 0.80077369 | D5: 1
A6: 43472 | B6: 0.62409412 | C6: 2.1779614 | D6: 1.7870574
A7: 43474 | B7: 0.66160119 | C7: 1.0091062 | D7: 1
A8: 43475 | B8: 0.91058824 | C8: 1.8035332 | D8: 1.7034199
A9: 43476 | B9: 1.2302882 | C9: 2.0065635 | D9: 1.9913043
A10: 43477 | B10: 0.45882353 | C10: 0.98834499 | D10: 0.8509434
A11: 43479 | B11: 0.1352381 | C11: 0.83738796 | D11: 1
A12: 43480 | B12: 0.47529412 | C12: 1.0126013 | D12: 0.92
A13: 43481 | B13: 1.4423529 | C13: 2.2001981 | D13: 1.8472149
A14: 43482 | B14: 1.5152941 | C14: 1.3479496 | D14: 1.6754803
A15: 43483 | B15: 0.90731765 | C15: 2.2345555 | D15: 1.6746783
... A17: 43486 | B17: 0.95294118 | C17: 1.0114478 | D17: 0.98180204
A18: Total general | B18: 11.2851 | C18: 20.313214 | D18: 19.300318

Sheet KG DE SCRAP
A1: DATE | B1: KG SCRAP ROLL COIL | C1: BOBINA KG | D1: KG COIL DAMAGES AND PROCESS ADJUST | E1: QUARENTINE PIECES | F1: Columna2
A2: 45474 | C2: 23.5 | F2: POR CADA 1300 PZAS HAY 2 KG DE SCRAP
A3: 45475
A4: 45476 | C4: 22
A5: 45477
A6: 45478 | D6: 11
A7: 45479
A8: 45480 | C8: 7
A9: 45481
A10: 45482 | C10: 13.5
A11: 45483
A12: 45484
A13: 45485
A14: 45486
A15: 45487
A16: 45488
A17: 45489 | B17: 26
A18: 45490 | C18: 25.5
A19: 45491
A20: 45492
A21: 45493
A22: 45494
A23: 45495
A24: 45496 | C24: 29
A25: 45497
A26: 45498
A27: 45499
A28: 45500
A29: 45501
A30: 45502
A31: 45503
A32: 45504
A33: 45505
A34: 45506
A35: 45507
A36: 45508
... A43: 45515
A44: 45516 | B44: 7
A45: 45517
A46: 45518
...

Sheet Hoja2
A1: REF VLOOK UP | B1: TURNO | C1: FECHA | D1: LIBERACIÓN | E1: PROCESO | F1: MTTO OTROS | G1: TIEMPO EXTRA | H1: TIEMPO CALCULADO | I1: TIEMPO PLANIFICADO | J1: TIEMPO OPERATIVO | K1: RESULTADO DISPONIBILIDAD | L1: PIEZAS PRODUCIDAS | M1: ESTANDAR | N1: MIN X HORAS | O1: RESULTADO RENDIMIENTO | P1: PIEZAS BUENAS | Q1: PIEZAS PRODUCIDAS2 | R1: Scrap de arranque | S1: Scrap de cambio de bobina | T1: Estampado | U1: Formado | V1: Condición de ondulación | W1: Scrap de corte | X1: Falla de soldadura | Y1: Longitud del tubo | Z1: Corona | AA1: DC01 | AB1: DC03 | AC1: Rechazo de maquina | AD1: Peso de scrap de la maquina (kg) | AE1: Scrap de empaque | AF1: Limado manual | AG1: Rodillo | AH1: Labio levantado | AI1: Rebaba de ventana | AJ1: Washer | AK1: Prensa | AL1: Diimples marcados | AM1: Couples | AN1: Doble grabado | AO1: Pieza larga | AP1: Pieza corta | AQ1: Soldadura dañada | AR1: Mal limada | AS1: Pieza con golpes | AT1: Caidas al piso | AU1: Soldadura desaliniada | AV1: Otro | AW1: Pruebas de calidad | AX1: Ajsutes de Ingenieria | AY1: Ajustes de MTTO | AZ1: QA TOTAL | BA1: Week Number | BB1: SCRAP | BC1: RESULTADO CALIDAD | BD1: RESULTADO OEE
A2: 1 | B2: 1 | C2: 43467 | D2: 51 | E2: 9 | G2: 0 | H2: 425 | I2: 425 | J2: 365 | K2: 0.85882353 | L2: 1932 | M2: 330 | N2: 60 | O2: 0.96239103 | P2: 1932 | Q2: 1932 | AD2: 22 | AZ2: 0 | BA2: 1 | BB2: 0 | BC2: 1 | BD2: 0.82652406
A3: 2 | B3: 1 | C3: 43468 | F3: 525 | AZ3: 0
A4: 3 | B4: 1 | C4: 43469 | D4: 81 | E4: 175 | G4: 45 | H4: 425 | I4: 470 | J4: 214 | K4: 0.45531915 | L4: 1190 | M4: 330 | N4: 60 | O4: 1.011045 | P4: 1070 | Q4: 1190 | R4: 100 | X4: 120 | AD4: 54 | AZ4: 120 | BA4: 1 | BB4: 120 | BC4: 0.89915966 | BD4: 0.4139265
A5: 4 | B5: 1 | C5: 43470 | D5: 140 | E5: 18 | F5: 220 | G5: 0 | H5: 425 | I5: 425 | J5: 47 | K5: 0.11058824 | L5: 207 | M5: 330 | N5: 60 | O5: 0.80077369 | P5: 207 | Q5: 207 | R5: 100 | S5: 107 | AD5: 71 | AZ5: 0 | BA5: 1 | BB5: 0 | BC5: 1 | BD5: 0.08855615
A6: 5 | B6: 1 | C6: 43472 | D6: 47 | E6: 41 | F6: 155 | H6: 425 | I6: 425 | J6: 182 | K6: 0.42823529 | L6: 1170 | M6: 330 | N6: 60 | O6: 1.1688312 | P6: 1088 | Q6: 1170 | R6: 100 | U6: 15 | X6: 33 | Y6: 12 | AD6: 15 | AS6: 37 | AZ6: 82 | BA6: 2 | BB6: 82 | BC6: 0.92991453 | BD6: 0.46545455
A7: 6 | B7: 2 | C7: 43472 | D7: 90 | E7: 10 | F7: 241.76 | H7: 425 | I7: 425 | J7: 83.24 | K7: 0.19585882 | L7: 462 | M7: 330 | N7: 60 | O7: 1.0091302 | P7: 396 | Q7: 462 | T7: 66 | AD7: 38 | AZ7: 66 | BA7: 2 | BB7: 66 | BC7: 0.85714286 | BD7: 0.16941176
A8: 7 | B8: 1 | C8: 43474 | F8: 525 | AZ8: 0 | BA8: 2
A9: 8 | B9: 2 | C9: 43474 | D9: 161 | G9: 50.77 | H9: 425 | I9: 475.77 | J9: 314.77 | K9: 0.66160119 | L9: 1747 | M9: 330 | N9: 60 | O9: 1.0091062 | P9: 1747 | Q9: 1747 | R9: 89 | AD9: 15.7 | AX9: 256 | AZ9: 256 | BA9: 2 | BB9: 0 | BC9: 1 | BD9: 0.66762588
A10: 9 | B10: 1 | C10: 43475 | D10: 145 | E10: 82 | H10: 425 | I10: 425 | J10: 198 | K10: 0.46588235 | L10: 863 | M10: 330 | N10: 60 | O10: 0.79247016 | P10: 745 | Q10: 863 | R10: 100 | AD10: 9.45 | AP10: 12 | AQ10: 23 | AR10: 4 | AS10: 69 | AT10: 10 | AZ10: 118 | BA10: 2 | BB10: 118 | BC10: 0.86326767 | BD10: 0.31871658
A11: 10 | B11: 2 | C11: 43475 | D11: 225 | E11: 11 | H11: 425 | I11: 425 | J11: 189 | K11: 0.44470588 | L11: 1051 | M11: 330 | N11: 60 | O11: 1.011063 | P11: 883 | Q11: 1051 | S11: 160 | U11: 138 | Y11: 7 | AD11: 69 | AE11: 17 | AF11: 6 | AZ11: 30 | BA11: 2 | BB11: 168 | BC11: 0.84015224 | BD11: 0.37775401
A12: 11 | B12: 1 | C12: 43476 | D12: 220 | E12: 13 | H12: 425 | I12: 425 | J12: 192 | K12: 0.45176471 | L12: 1053 | M12: 330 | N12: 60 | O12: 0.99715909 | P12: 1053 | Q12: 1053 | R12: 1 | AD12: 37 | AZ12: 0 | BA12: 2 | BB12: 0 | BC12: 1 | BD12: 0.45048128
A13: 12 | B13: 2 | C13: 43476 | D13: 162 | E13: 3 | G13: 320 | H13: 425 | I13: 745 | J13: 580 | K13: 0.77852349 | L13: 3220 | M13: 330 | N13: 60 | O13: 1.0094044 | P13: 3192 | Q13: 3220 | R13: 18 | S13: 50 | AD13: 29 | AQ13: 30 | AU13: 30 | AZ13: 30 | BA13: 2 | BB13: 28 | BC13: 0.99130435 | BD13: 0.77901159
A14: 13 | B14: 1 | C14: 43477 | D14: 150 | E14: 80 | H14: 425 | I14: 425 | J14: 195 | K14: 0.45882353 | L14: 1060 | M14: 330 | N14: 60 | O14: 0.98834499 | P14: 902 | Q14: 1060 | R14: 100 | S14: 20 | W14: 32 | AD14: 9.75 | AP14: 1 | AQ14: 94 | AS14: 11 | AZ14: 138 | BA14: 2 | BB14: 158 | BC14: 0.8509434 | BD14: 0.38588235
A15: 14 | B15: 1 | C15: 43479 | D15: 396 | E15: 58 | H15: 525 | I15: 525 | J15: 71 | K15: 0.1352381 | L15: 327 | M15: 330 | N15: 60 | O15: 0.83738796 | P15: 327 | Q15: 327 | AD15: 3.55 | AX15: 322 | AZ15: 322 | BA15: 3 | BB15: 0 | BC15: 1 | BD15: 0.11324675
A16: 15 | B16: 2 | C16: 43480 | D16: 39 | E16: 30 | F16: 180 | H16: 425 | I16: 425 | J16: 202 | K16: 0.47529412 | L16: 1125 | M16: 330 | N16: 60 | O16: 1.0126013 | P16: 1035 | Q16: 1125 | R16: 100 | U16: 1 | V16: 75 | X16: 9 | AD16: 22 | AT16: 6 | AZ16: 90 | BA16: 3 | BB16: 90 | BC16: 0.92 | BD16: 0.44278075
A17: 16 | B17: 1 | C17: 43481 | D17: 46 | E17: 54 | H17: 425 | I17: 425 | J17: 325 | K17: 0.76470588 | L17: 1949 | M17: 330 | N17: 60 | O17: 1.0903497 | P17: 1751 | Q17: 1949 | R17: 100 | V17: 82 | W17: 7 | AH17: 16 | AP17: 59 | AS17: 33 | AT17: 1 | AZ17: 198 | BA17: 3 | BB17: 198 | BC17: 0.89840944 | BD17: 0.74909091
A18: 17 | B18: 2 | C18: 43481 | D18: 53 | E18: 84 | H18: 425 | I18: 425 | J18: 288 | K18: 0.67764706 | L18: 1758 | M18: 330 | N18: 60 | O18: 1.1098485 | P18: 1668 | Q18: 1758 | V18: 19 | AK18: 4 | AL18: 20 | AP18: 5 | AQ18: 8 | AR18: 24 | AS18: 10 | AZ18: 90 | BA18: 3 | BB18: 90 | BC18: 0.94880546 | BD18: 0.71358289
A19: 18 | B19: 1 | C19: 43482 | F19: 124 | H19: 425 | I19: 425 | J19: 301 | K19: 0.70823529 | L19: 544 | M19: 330 | N19: 60 | O19: 0.32860163 | P19: 428 | Q19: 544 | R19: 100 | W19: 3 | Y19: 22 | AE19: 79 | AL19: 12 | AZ19: 116 | BA19: 3 | BB19: 116 | BC19: 0.78676471 | BD19: 0.1831016
A20: 19 | B20: 2 | C20: 43482 | D20: 2 | E20: 80 | H20: 425 | I20: 425 | J20: 343 | K20: 0.80705882 | L20: 1923 | M20: 330 | N20: 60 | O20: 1.019348 | P20: 1709 | Q20: 1923 | S20: 38 | V20: 13 | W20: 62 | AH20: 7 | AO20: 7 | AQ20: 29 | AR20: 6 | AS20: 1 | AT20: 10 | AX20: 86 | AZ20: 214 | BA20: 3 | BB20: 214 | BC20: 0.88871555 | BD20: 0.73112299
A21: 20 | B21: 1 | C21: 43483 | E21: 152 | H21: 425 | I21: 425 | J21: 273 | K21: 0.64235294 | L21: 1840 | M21: 330 | N21: 60 | O21: 1.2254412 | P21: 1736 | Q21: 1840 | R21: 100 | AH21: 1 | AI21: 2 | AP21: 29 | AR21: 2 | AS21: 58 | AT21: 12 | AU21: 4 | AZ21: 104 | BA21: 3 | BB21: 104 | BC21: 0.94347826 | BD21: 0.7426738
A22: 21 | B22: 2 | C22: 43483 | D22: 259 | F22: 138 | H22: 425 | I22: 425 | J22: 112.61 | K22: 0.26496471 | L22: 625 | M22: 330 | N22: 60 | O22: 1.0091143 | P22: 457 | Q22: 625 | V22: 10 | W22: 23 | AP22: 4 | AR22: 6 | AS22: 69 | AT22: 2 | AU22: 7 | AX22: 54 | AZ22: 168 | BA22: 3 | BB22: 168 | BC22: 0.7312 | BD22: 0.19550802
A23: 22 | B23: 2 | C23: 43484 | D23: 163 | E23: 123 | G23: 105.7 | H23: 525 | I23: 630.7 | J23: 344.7 | K23: 0.5465356 | L23: 1724 | M23: 330 | N23: 60 | O23: 0.90935464 | P23: 1671 | Q23: 1724 | R23: 100 | V23: 3 | W23: 30 | X23: 20 | AZ23: 53 | BA23: 3 | BB23: 53 | BC23: 0.96925754 | BD23: 0.48171584
A24: 23 | B24: 2 | C24: 43486 | D24: 20 | H24: 425 | I24: 425 | J24: 405 | K24: 0.95294118 | L24: 2253 | M24: 330 | N24: 60 | O24: 1.0114478 | P24: 2212 | Q24: 2253 | R24: 100 | AH24: 11 | AO24: 5 | AP24: 3 | AQ24: 1 | AR24: 13 | AS24: 9 | AT24: 4 | AV24: 6 | AZ24: 41 | BA24: 4 | BB24: 41 | BC24: 0.98180204 | BD24: 0.94631016
A25: 24 | B25: 2 | C25: 43487 | D25: 166 | E25: 98 | F25: 80 | G25: 270 | H25: 425 | I25: 695 | J25: 351 | K25: 0.50503597 | L25: 1910 | M25: 330 | N25: 60 | O25: 0.98938099 | P25: 1910 | Q25: 1910 | S25: 104 | AQ25: 3 | AR25: 10 | AS25: 47 | AT25: 1 | AV25: 14 | AZ25: 61 | BA25: 4 | BB25: 61 | BC25: 1 | BD25: 0.49967299
A26: 25 | B26: 2 | C26: 43488 | D26: 116 | E26: 12 | F26: 23 | H26: 375 | I26: 375 | J26: 224 | K26: 0.59733333 | L26: 1243 | M26: 330 | N26: 60 | O26: 1.0089286 | P26: 1170 | Q26: 1243 | R26: 72 | AP26: 2 | AS26: 66 | AT26: 5 | AV26: 3 | AZ26: 73 | BA26: 4 | BB26: 73 | BC26: 0.94127112 | BD26: 0.56727273
A27: 26 | B27: 2 | C27: 43489 | D27: 104 | E27: 25 | F27: 26 | H27: 375 | I27: 375 | J27: 220 | K27: 0.58666667 | L27: 1222 | M27: 330 | N27: 60 | O27: 1.0099174 | P27: 1144 | Q27: 1222 | R27: 100 | S27: 57 | AH27: 1 | AO27: 8 | AP27: 7 | AR27: 33 | AS27: 36 | AT27: 1 | AV27: 11 | AZ27: 78 | BA27: 4 | BB27: 78 | BC27: 0.93617021 | BD27: 0.55466667
A28: 27 | B28: 2 | C28: 43490 | G28: 185 | H28: 425 | I28: 610 | J28: 610 | K28: 1 | L28: 3368 | M28: 330 | N28: 60 | O28: 1.0038748 | P28: 3121 | Q28: 3368 | R28: 100 | S28: 165 | U28: 4 | W28: 1 | X28: 1 | AF28: 5 | AG28: 11 | AH28: 39 | AI28: 1 | AK28: 36 | AO28: 12 | AP28: 29 | AR28: 17 | AS28: 100 | AT28: 7 | AV28: 3 | AZ28: 247 | BA28: 4 | BB28: 247 | BC28: 0.92666271 | BD28: 0.93025335
A29: 28 | B29: 2 | C29: 43493 | D29: 25 | H29: 375 | I29: 375 | J29: 350 | K29: 0.93333333 | L29: 1945 | M29: 330 | N29: 60 | O29: 1.0103896 | P29: 1935 | Q29: 1945 | R29: 100 | S29: 75 | AR29: 2 | AS29: 8 | AV29: 4 | AZ29: 10 | BA29: 5 | BB29: 10 | BC29: 0.99485861 | BD29: 0.93818182
A30: 29 | B30: 2 | C30: 43494 | G30: 122 | H30: 375 | I30: 497 | J30: 497 | K30: 1 | L30: 2759 | M30: 330 | N30: 60 | O30: 1.0093287 | P30: 2575 | Q30: 2759 | R30: 100 | S30: 84 | AH30: 2 | AO30: 13 | AR30: 11 | AS30: 38 | AT30: 1 | AV30: 34 | AZ30: 52 | BA30: 5 | BB30: 52 | BC30: 0.93330917 | BD30: 0.94201573
A31: 30 | B31: 2 | C31: 43495 | D31: 230 | E31: 24 | H31: 375 | I31: 375 | J31: 121 | K31: 0.32266667 | L31: 674 | M31: 330 | N31: 60 | O31: 1.0127724 | P31: 626 | Q31: 674 | AK31: 12 | AO31: 10 | AP31: 2 | AR31: 11 | AS31: 23 | AU31: 2 | AV31: 2 | AZ31: 48 | BA31: 5 | BB31: 48 | BC31: 0.92878338 | BD31: 0.30351515
A32: 31 | B32: 2 | C32: 43496 | G32: 154 | H32: 375 | I32: 529 | J32: 529 | K32: 1 | L32: 2936 | M32: 330 | N32: 60 | O32: 1.0091081 | P32: 2936 | Q32: 2936 | R32: 100 | S32: 98 | AP32: 59 | AR32: 38 | AS32: 14 | AV32: 11 | AZ32: 111 | BA32: 5 | BB32: 111 | BC32: 1 | BD32: 1.0091081

Sheet PPM´s
BO17: Meses | BP17: (Varios elementos)
BO18: FECHA | BP18: (Todas)
A20: Etiquetas de fila | B20: Suma de PPM´s | G20: FECHA | H20: (Varios elementos) | P20: Etiquetas de fila | Q20: Sum of PIEZAS PRODUCIDAS2 | R20: Sum of SCRAP | S20: Suma de PPM´s | AA20: Etiquetas de fila | AB20: Suma de PMM´s ACTUADORES | AM20: Etiquetas de fila | AN20: Sum of PIEZAS PRODUCIDAS | AO20: Sum of SCRAP | AP20: Suma de PMM´s ACTUADORES | BO20: Valores
A21: ene | B21: 56578.947 | P21: 1 | Q21: 3329 | R21: 120 | S21: 36046.861 | AA21: ene | AB21: 254.06504 | AM21: 1 | AN21: 1644 | AO21: 0 | AP21: 0 | BO21: Other | BP21: 9
A22: feb | B22: 40790.375 | G22: Valores | P22: 2 | Q22: 10626 | R22: 620 | S22: 58347.45 | AA22: feb | AB22: 1295.6964 | AM22: 2 | AN22: 4236 | AO22: 1 | AP22: 236.07177 | BO22: Sum of Prensado no conforme Marcas Fisura | BP22: 3
A23: mar | B23: 28430.462 | G23: Pieces with hits | H23: 886 | P23: 3 | Q23: 11815 | R23: 1033 | S23: 87431.231 | AA23: mar | AB23: 1042.9448 | AM23: 3 | AN23: 3894 | AO23: 1 | AP23: 256.80534 | BO23: Seal leak | BP23: 22
A24: abr | B24: 97069.02 | G24: Short piece | H24: 279 | P24: 4 | Q24: 9996 | R24: 500 | S24: 50020.008 | AA24: abr | AB24: 778.90286 | AM24: 4 | AN24: 2034 | AO24: 1 | AP24: 491.64208 | BO24: Engraving Missing Position Incomplete
A25: Total general | B25: 54362.286 | G25: Suma de Condición de ondulación | H25: 219 | P25: 5 | Q25: 11049 | R25: 295 | S25: 26699.249 | AA25: Total general | AB25: 855.9499 | AM25: 7 | AN25: 4437 | AO25: 4 | AP25: 901.51003 | BO25: Missing spring | BP25: 3
G26: Welding Failure | H26: 185 | P26: 6 | R26: 67 | AM26: 8 | AN26: 5835 | AO26: 8 | AP26: 1371.0368 | BO26: Surface treatment
G27: Badly filed piece | H27: 257 | P27: 7 | Q27: 10493 | R27: 550 | S27: 52415.896 | AM27: 9 | AN27: 1766 | AO27: 11 | AP27: 6228.7656 | BO27: Burrs Dents Damage Marks Sharp-edges
G28: Bad welding | H28: 333 | P28: 8 | Q28: 13326 | R28: 457 | S28: 34293.862 | AM28: 10 | AN28: 6520 | AO28: 3 | AP28: 460.1227 | BO28: Crimping NOK Damaged
G29: Sum of Formado | H29: 160 | P29: 9 | Q29: 4115 | R29: 103 | S29: 25030.377 | AM29: 11 | AN29: 959 | AO29: 0 | AP29: 0 | BO29: Diameter NOK
G30: Cutter | H30: 159 | P30: 10 | Q30: 11585 | R30: 352 | S30: 30384.117 | AM30: 12 | AN30: 4008 | AO30: 3 | AP30: 748.50299 | BO30: Height NOK | BP30: 1
G31: Sum of Otro | H31: 257 | P31: 11 | Q31: 11970 | R31: 220 | S31: 18379.282 | AM31: 13 | AN31: 3580 | AO31: 2 | AP31: 558.65922 | BO31: Interrupted Process by safety sensor
G32: Suma de Labio levantado | H32: 165 | P32: 12 | Q32: 9657 | R32: 192 | S32: 19881.951 | AM32: 14 | AN32: 2244 | AO32: 0 | AP32: 0 | BO32: Crimping NOK deformed
G33: Tube Length | H33: 41 | P33: 13 | Q33: 11986 | R33: 521 | S33: 43467.379 | AM33: 15 | AN33: 5110 | AO33: 6 | AP33: 1174.1683 | BO33: JIG FASE 45 Failure
G34: Stamp | H34: 66 | P34: 14 | Q34: 6409 | R34: 625 | S34: 97519.114 | AM34: 16 | AN34: 923 | AO34: 1 | AP34: 1083.4236 | BO34: DMC code not correct
G35: Misaligned welding | H35: 112 | P35: 15 | Q35: 6395 | R35: 1426 | S35: 222986.71 | AM35: 18 | AN35: 710 | AO35: 0 | AP35: 0 | BO35: Hysteresis failure
G36: Suma de Prensa | H36: 117 | P36: 16 | Q36: 9124 | R36: 985 | S36: 107957.04 | AM36: Total general | AN36: 47900 | AO36: 41 | AP36: 855.9499 | BO36: Engraving malfunction
G37: Falls to the floor | H37: 90 | P37: 17 | Q37: 10754 | R37: 345 | S37: 32081.086 | BO37: Engraving not readable
G38: Suma de Pieza larga | H38: 67 | P38: 18 | Q38: 2221 | R38: 7 | S38: 3151.7335 | BO38: Fitting Short Loose Capping Not weld
G39: Suma de Rodillo | H39: 41 | P39: Total general | Q39: 154850 | R39: 8418 | S39: 54362.286
G40: Suma de Diimples marcados | H40: 183
G41: Manual filing | H41: 11
G42: Suma de Couples | H42: 12
G43: Sum of Doble grabado | H43: 21
G44: Suma de Rebaba de ventana | H44: 48
G45: Sum of Washer
G46: Sum of DC03
G47: Sum of DC01
G48: Sum of Corona

Sheet GRAFICA PRENSA
A1: Día | B1: OEE
A2: 3 | B2: 0.63510848
A3: 4 | B3: 0.70628571
A4: 7 | B4: 0.53028571
A5: 8 | B5: 0.22857143
A6: 10 | B6: 0.33752381
A7: 10 | B7: 0.57485714
A8: 11 | B8: 0.14209524
A9: 11 | B9: 0.80609524
A10: 12 | B10: 0.2567619
A11: 14 | B11: 0.14590476
A12: 14 | B12: 0.36
A13: 16 | B13: 0.36952381
... A36: 43501 | B36: 0.5305
A37: TOTAL | B37: =IFERROR(AVERAGE(B2:B22),"") -> 0.48188507

Sheet GRAFICA LEAK TEST
A1: Día | B1: OEE
A2: 3 | B2: 1
A3: 4 | B3: 0.91708598
A4: 5 | B4: 0.76761905
A5: 7 | B5: 0.50552381
A6: 8 | B6: 0.10171429
A7: 10 | B7: 0.37748918
A8: 11 | B8: 0.49212121
A9: 11 | B9: 0.97947214
A10: 12 | B10: 0.45229437
A11: 14 | B11: 0.34330401
A12: 16 | B12: 0.38510823
A13: 16 | B13: 0.62326491
... A35: 43501 | B35: 0.6053
A36: TOTAL | B36: =IFERROR(AVERAGE(B2:B20),"") -> 0.55652074

Sheet TIMEPO CAIDO
B1: ESTUDIO DE TIEMPOS
B2: PRODUCCION | I2: CALIDAD
A3: fecha | B3: PROCESO DE PRODUCCION | C3: HORA INICIO | D3: HORA PARO | E3: TIEMPO CAIDO | F3: MIN | G3: NOTAS | H3: HORA ENTREGA A CALIDAD | I3: RESULTADO DE CALIDAD | J3: HORA DE ENTREGA DE CALIDAD A PRODUCCION | K3: TIEMPO CAIDO | L3: MIN | M3: NOTAS | N3: TECNICO DE CALIDAD
C4: 0.060416667 | D4: 0.068055556 | E4: =D4-C4 -> 0.0076388889 | H4: 0.29513889 | J4: 0.32291667 | K4: =J4-H4 -> 0.027777778
C5: 0.083333333 | D5: 0.090972222 | E5: =D5-C5 -> 0.0076388889
C6: 0.10555556 | D6: 0.11319444 | E6: =D6-C6 -> 0.0076388889
C7: 0.12013889 | D7: 0.13263889 | E7: =D7-C7 -> 0.0125
C8: 0.13888889 | D8: 0.15277778 | E8: =D8-C8 -> 0.013888889
C9: 0.16041667 | D9: 0.17013889 | E9: =D9-C9 -> 0.0097222222
E10: =D10-C10 -> 0
E11: =D11-C11 -> 0
B12: AJUSTES POR PROCESOS

Sheet SPEED FACTOR REA
A1: Ref Vlook Cap | B1: Numero de semana | C1: Fecha | D1: P/N | E1: Piezas produccidas | F1: Minutos de presencia | G1: Minutos téoricos | H1: PZ/h | I1: OP1 | J1: OP2 | K1: OP3 | L1: Numero OP | M1: Minutos teoricos totales | N1: Minutos de presencia totales | O1: Minutos pagados totales | P1: % SF | R1: eff
A2: =+'OEE REA'!A3 -> 1 | B2: =WEEKNUM(C2) -> 2 | C2: =+'OEE REA'!D3 -> 45663 | D2: +'OEE REA'!B3 | E2: =VLOOKUP(A2,'OEE REA'!A:AO,13,FALSE) -> 56 | F2: =VLOOKUP(A2,'OEE REA'!A:AO,11,FALSE) -> 255 | G2: =IFERROR(E2/H2*60,"") -> 21.960784 | H2: =VLOOKUP(A2,'OEE REA'!A:AO,14,FALSE) -> 153 | L2: 1 | M2: =IFERROR(G2*L2,"") -> 21.960784 | N2: =IFERROR(F2*L2,"") -> 255 | O2: =IFERROR('OEE REA'!J3*'SPEED FACTOR REA'!L2,"") -> 300 | P2: =IFERROR(N2/M2,"") -> 11.611607 | R2: =G2/O2 -> 0.073202614
A3: =+'OEE REA'!A4 -> 2 | B3: =WEEKNUM(C3) -> 2 | C3: =+'OEE REA'!D4 -> 45663 | D3: +'OEE REA'!B4 | E3: =VLOOKUP(A3,'OEE REA'!A:AO,13,FALSE) -> 0 | F3: =VLOOKUP(A3,'OEE REA'!A:AO,11,FALSE) -> 240 | G3: =IFERROR(E3/H3*60,"") -> 0 | H3: =VLOOKUP(A3,'OEE REA'!A:AO,14,FALSE) -> 153 | L3: 1 | M3: =IFERROR(G3*L3,"") -> 0 | N3: =IFERROR(F3*L3,"") -> 240 | O3: =IFERROR('OEE REA'!J4*'SPEED FACTOR REA'!L3,"") -> 240 | P3: =IFERROR(N3/M3,"") | R3: =G3/O3 -> 0
A4: =+'OEE REA'!A5 -> 3 | B4: =WEEKNUM(C4) -> 2 | C4: =+'OEE REA'!D5 -> 45663 | D4: +'OEE REA'!B5 | E4: =VLOOKUP(A4,'OEE REA'!A:AO,13,FALSE) -> 377 | F4: =VLOOKUP(A4,'OEE REA'!A:AO,11,FALSE) -> 360 | G4: =IFERROR(E4/H4*60,"") -> 147.84314 | H4: =VLOOKUP(A4,'OEE REA'!A:AO,14,FALSE) -> 153 | L4: 1 | M4: =IFERROR(G4*L4,"") -> 147.84314 | N4: =IFERROR(F4*L4,"") -> 360 | O4: =IFERROR('OEE REA'!J5*'SPEED FACTOR REA'!L4,"") -> 360 | P4: =IFERROR(N4/M4,"") -> 2.4350133 | R4: =G4/O4 -> 0.41067538
A5: =+'OEE REA'!A6 -> 4 | B5: =WEEKNUM(C5) -> 2 | C5: =+'OEE REA'!D6 -> 45664 | D5: +'OEE REA'!B6 | E5: =VLOOKUP(A5,'OEE REA'!A:AO,13,FALSE) -> 660 | F5: =VLOOKUP(A5,'OEE REA'!A:AO,11,FALSE) -> 570 | G5: =IFERROR(E5/H5*60,"") -> 258.82353 | H5: =VLOOKUP(A5,'OEE REA'!A:AO,14,FALSE) -> 153 | L5: 1 | M5: =IFERROR(G5*L5,"") -> 258.82353 | N5: =IFERROR(F5*L5,"") -> 570 | O5: =IFERROR('OEE REA'!J6*'SPEED FACTOR REA'!L5,"") -> 600 | P5: =IFERROR(N5/M5,"") -> 2.2022727 | R5: =G5/O5 -> 0.43137255
A6: =+'OEE REA'!A7 -> 5 | B6: =WEEKNUM(C6) -> 2 | C6: =+'OEE REA'!D7 -> 45664 | D6: +'OEE REA'!B7 | E6: =VLOOKUP(A6,'OEE REA'!A:AO,13,FALSE) -> 459 | F6: =VLOOKUP(A6,'OEE REA'!A:AO,11,FALSE) -> 300 | G6: =IFERROR(E6/H6*60,"") -> 180 | H6: =VLOOKUP(A6,'OEE REA'!A:AO,14,FALSE) -> 153 | L6: 1 | M6: =IFERROR(G6*L6,"") -> 180 | N6: =IFERROR(F6*L6,"") -> 300 | O6: =IFERROR('OEE REA'!J7*'SPEED FACTOR REA'!L6,"") -> 540 | P6: =IFERROR(N6/M6,"") -> 1.6666667 | R6: =G6/O6 -> 0.33333333
A7: =+'OEE REA'!A8 -> 6 | B7: =WEEKNUM(C7) -> 2 | C7: =+'OEE REA'!D8 -> 45665 | D7: +'OEE REA'!B8 | E7: =VLOOKUP(A7,'OEE REA'!A:AO,13,FALSE) -> 1058 | F7: =VLOOKUP(A7,'OEE REA'!A:AO,11,FALSE) -> 566 | G7: =IFERROR(E7/H7*60,"") -> 414.90196 | H7: =VLOOKUP(A7,'OEE REA'!A:AO,14,FALSE) -> 153 | M7: =IFERROR(G7*L7,"") -> 0 | N7: =IFERROR(F7*L7,"") -> 0 | O7: =IFERROR('OEE REA'!J8*'SPEED FACTOR REA'!L7,"") -> 0 | P7: =IFERROR(N7/M7,"") | R7: =G7/O7 -> #DIV/0!
A8: =+'OEE REA'!A9 -> 7 | B8: =WEEKNUM(C8) -> 2 | C8: =+'OEE REA'!D9 -> 45665 | D8: +'OEE REA'!B9 | E8: =VLOOKUP(A8,'OEE REA'!A:AO,13,FALSE) -> 1170 | F8: =VLOOKUP(A8,'OEE REA'!A:AO,11,FALSE) -> 540 | G8: =IFERROR(E8/H8*60,"") -> 458.82353 | H8: =VLOOKUP(A8,'OEE REA'!A:AO,14,FALSE) -> 153 | M8: =IFERROR(G8*L8,"") -> 0 | N8: =IFERROR(F8*L8,"") -> 0 | O8: =IFERROR('OEE REA'!J9*'SPEED FACTOR REA'!L8,"") -> 0 | P8: =IFERROR(N8/M8,"") | R8: =G8/O8 -> #DIV/0!
A9: =+'OEE REA'!A10 -> 8 | B9: =WEEKNUM(C9) -> 2 | C9: =+'OEE REA'!D10 -> 45666 | D9: +'OEE REA'!B10 | E9: =VLOOKUP(A9,'OEE REA'!A:AO,13,FALSE) -> 1208 | F9: =VLOOKUP(A9,'OEE REA'!A:AO,11,FALSE) -> 555 | G9: =IFERROR(E9/H9*60,"") -> 473.72549 | H9: =VLOOKUP(A9,'OEE REA'!A:AO,14,FALSE) -> 153 | M9: =IFERROR(G9*L9,"") -> 0 | N9: =IFERROR(F9*L9,"") -> 0 | O9: =IFERROR('OEE REA'!J10*'SPEED FACTOR REA'!L9,"") -> 0 | P9: =IFERROR(N9/M9,"") | R9: =G9/O9 -> #DIV/0!
A10: =+'OEE REA'!A11 -> 9 | B10: =WEEKNUM(C10) -> 2 | C10: =+'OEE REA'!D11 -> 45666 | D10: +'OEE REA'!B11 | E10: =VLOOKUP(A10,'OEE REA'!A:AO,13,FALSE) -> 816 | F10: =VLOOKUP(A10,'OEE REA'!A:AO,11,FALSE) -> 240 | G10: =IFERROR(E10/H10*60,"") -> 320 | H10: =VLOOKUP(A10,'OEE REA'!A:AO,14,FALSE) -> 153 | M10: =IFERROR(G10*L10,"") -> 0 | N10: =IFERROR(F10*L10,"") -> 0 | O10: =IFERROR('OEE REA'!J11*'SPEED FACTOR REA'!L10,"") -> 0 | P10: =IFERROR(N10/M10,"") | R10: =G10/O10 -> #DIV/0!
A11: =+'OEE REA'!A12 -> 10 | B11: =WEEKNUM(C11) -> 2 | C11: =+'OEE REA'!D12 -> 45666 | D11: +'OEE REA'!B12 | E11: =VLOOKUP(A11,'OEE REA'!A:AO,13,FALSE) -> 114 | F11: =VLOOKUP(A11,'OEE REA'!A:AO,11,FALSE) -> 185 | G11: =IFERROR(E11/H11*60,"") -> 44.705882 | H11: =VLOOKUP(A11,'OEE REA'!A:AO,14,FALSE) -> 153 | M11: =IFERROR(G11*L11,"") -> 0 | N11: =IFERROR(F11*L11,"") -> 0 | O11: =IFERROR('OEE REA'!J12*'SPEED FACTOR REA'!L11,"") -> 0 | P11: =IFERROR(N11/M11,"") | R11: =G11/O11 -> #DIV/0!
A12: =+'OEE REA'!A13 -> 11 | B12: =WEEKNUM(C12) -> 2 | C12: =+'OEE REA'!D13 -> 45667 | D12: +'OEE REA'!B13 | E12: =VLOOKUP(A12,'OEE REA'!A:AO,13,FALSE) -> 894 | F12: =VLOOKUP(A12,'OEE REA'!A:AO,11,FALSE) -> 497 | G12: =IFERROR(E12/H12*60,"") -> 350.58824 | H12: =VLOOKUP(A12,'OEE REA'!A:AO,14,FALSE) -> 153 | M12: =IFERROR(G12*L12,"") -> 0 | N12: =IFERROR(F12*L12,"") -> 0 | O12: =IFERROR('OEE REA'!J13*'SPEED FACTOR REA'!L12,"") -> 0 | P12: =IFERROR(N12/M12,"") | R12: =G12/O12 -> #DIV/0!
A13: =+'OEE REA'!A14 -> 12 | B13: =WEEKNUM(C13) -> 2 | C13: =+'OEE REA'!D14 -> 45667 | D13: +'OEE REA'!B14 | E13: =VLOOKUP(A13,'OEE REA'!A:AO,13,FALSE) -> 271 | F13: =VLOOKUP(A13,'OEE REA'!A:AO,11,FALSE) -> 240 | G13: =IFERROR(E13/H13*60,"") -> 106.27451 | H13: =VLOOKUP(A13,'OEE REA'!A:AO,14,FALSE) -> 153 | M13: =IFERROR(G13*L13,"") -> 0 | N13: =IFERROR(F13*L13,"") -> 0 | O13: =IFERROR('OEE REA'!J14*'SPEED FACTOR REA'!L13,"") -> 0 | P13: =IFERROR(N13/M13,"") | R13: =G13/O13 -> #DIV/0!
A14: =+'OEE REA'!A15 -> 13 | B14: =WEEKNUM(C14) -> 2 | C14: =+'OEE REA'!D15 -> 45667 | D14: +'OEE REA'!B15 | E14: =VLOOKUP(A14,'OEE REA'!A:AO,13,FALSE) -> 0 | F14: =VLOOKUP(A14,'OEE REA'!A:AO,11,FALSE) -> 205 | G14: =IFERROR(E14/H14*60,"") -> 0 | H14: =VLOOKUP(A14,'OEE REA'!A:AO,14,FALSE) -> 153 | M14: =IFERROR(G14*L14,"") -> 0 | N14: =IFERROR(F14*L14,"") -> 0 | O14: =IFERROR('OEE REA'!J15*'SPEED FACTOR REA'!L14,"") -> 0 | P14: =IFERROR(N14/M14,"") | R14: =G14/O14 -> #DIV/0!
A15: =+'OEE REA'!A16 -> 14 | B15: =WEEKNUM(C15) -> 3 | C15: =+'OEE REA'!D16 -> 45670 | D15: +'OEE REA'!B16 | E15: =VLOOKUP(A15,'OEE REA'!A:AO,13,FALSE) -> 756 | F15: =VLOOKUP(A15,'OEE REA'!A:AO,11,FALSE) -> 408 | G15: =IFERROR(E15/H15*60,"") -> 296.47059 | H15: =VLOOKUP(A15,'OEE REA'!A:AO,14,FALSE) -> 153 | M15: =IFERROR(G15*L15,"") -> 0 | N15: =IFERROR(F15*L15,"") -> 0 | O15: =IFERROR('OEE REA'!J16*'SPEED FACTOR REA'!L15,"") -> 0 | P15: =IFERROR(N15/M15,"") | R15: =G15/O15 -> #DIV/0!
A16: =+'OEE REA'!A17 -> 15 | B16: =WEEKNUM(C16) -> 3 | C16: =+'OEE REA'!D17 -> 45670 | D16: +'OEE REA'!B17 | E16: =VLOOKUP(A16,'OEE REA'!A:AO,13,FALSE) -> 860 | F16: =VLOOKUP(A16,'OEE REA'!A:AO,11,FALSE) -> 540 | G16: =IFERROR(E16/H16*60,"") -> 337.2549 | H16: =VLOOKUP(A16,'OEE REA'!A:AO,14,FALSE) -> 153 | M16: =IFERROR(G16*L16,"") -> 0 | N16: =IFERROR(F16*L16,"") -> 0 | O16: =IFERROR('OEE REA'!J17*'SPEED FACTOR REA'!L16,"") -> 0 | P16: =IFERROR(N16/M16,"") | R16: =G16/O16 -> #DIV/0!
A17: =+'OEE REA'!A18 -> 16 | B17: =WEEKNUM(C17) -> 3 | C17: =+'OEE REA'!D18 -> 45671 | D17: +'OEE REA'!B18 | E17: =VLOOKUP(A17,'OEE REA'!A:AO,13,FALSE) -> 867 | F17: =VLOOKUP(A17,'OEE REA'!A:AO,11,FALSE) -> 559 | G17: =IFERROR(E17/H17*60,"") -> 340 | H17: =VLOOKUP(A17,'OEE REA'!A:AO,14,FALSE) -> 153 | M17: =IFERROR(G17*L17,"") -> 0 | N17: =IFERROR(F17*L17,"") -> 0 | O17: =IFERROR('OEE REA'!J18*'SPEED FACTOR REA'!L17,"") -> 0 | P17: =IFERROR(N17/M17,"") | R17: =G17/O17 -> #DIV/0!
A18: =+'OEE REA'!A19 -> 17 | B18: =WEEKNUM(C18) -> 3 | C18: =+'OEE REA'!D19 -> 45671 | D18: +'OEE REA'!B19 | E18: =VLOOKUP(A18,'OEE REA'!A:AO,13,FALSE) -> 968 | F18: =VLOOKUP(A18,'OEE REA'!A:AO,11,FALSE) -> 540 | G18: =IFERROR(E18/H18*60,"") -> 379.60784 | H18: =VLOOKUP(A18,'OEE REA'!A:AO,14,FALSE) -> 153 | M18: =IFERROR(G18*L18,"") -> 0 | N18: =IFERROR(F18*L18,"") -> 0 | O18: =IFERROR('OEE REA'!J19*'SPEED FACTOR REA'!L18,"") -> 0 | P18: =IFERROR(N18/M18,"") | R18: =G18/O18 -> #DIV/0!
... A33: =+'OEE REA'!A34 -> 32 | B33: =WEEKNUM(C33) -> 4 | C33: =+'OEE REA'!D34 -> 45681 | D33: +'OEE REA'!B34 | E33: =VLOOKUP(A33,'OEE REA'!A:AO,13,FALSE) -> 1148 | F33: =VLOOKUP(A33,'OEE REA'!A:AO,11,FALSE) -> 555 | G33: =IFERROR(E33/H33*60,"") -> 450.19608 | H33: =VLOOKUP(A33,'OEE REA'!A:AO,14,FALSE) -> 153 | M33: =IFERROR(G33*L33,"") -> 0 | N33: =IFERROR(F33*L33,"") -> 0 | O33: =IFERROR('OEE REA'!J34*'SPEED FACTOR REA'!L33,"") -> 0 | P33: =IFERROR(N33/M33,"") | R33: =G33/O33 -> #DIV/0!
A34: =+'OEE REA'!A389 -> 386 | B34: =WEEKNUM(C34) -> 26 | C34: =+'OEE REA'!D389 -> 45835 | D34: +'OEE REA'!B35 | E34: =VLOOKUP(A34,'OEE REA'!A:AO,13,FALSE) -> 1030 | F34: =VLOOKUP(A34,'OEE REA'!A:AO,11,FALSE) -> 510 | G34: =IFERROR(E34/H34*60,"") -> 403.92157 | H34: =VLOOKUP(A34,'OEE REA'!A:AO,14,FALSE) -> 153 | M34: =IFERROR(G34*L34,"") -> 0 | N34: =IFERROR(F34*L34,"") -> 0 | O34: =IFERROR('OEE REA'!J389*'SPEED FACTOR REA'!L34,"") -> 0 | P34: =IFERROR(N34/M34,"") | R34: =G34/O34 -> #DIV/0!
A35: =+'OEE REA'!A390 -> 387 | B35: =WEEKNUM(C35) -> 26 | C35: =+'OEE REA'!D390 -> 45836 | D35: +'OEE REA'!B36 | E35: =VLOOKUP(A35,'OEE REA'!A:AO,13,FALSE) -> 935 | F35: =VLOOKUP(A35,'OEE REA'!A:AO,11,FALSE) -> 435 | G35: =IFERROR(E35/H35*60,"") -> 366.66667 | H35: =VLOOKUP(A35,'OEE REA'!A:AO,14,FALSE) -> 153 | M35: =IFERROR(G35*L35,"") -> 0 | N35: =IFERROR(F35*L35,"") -> 0 | O35: =IFERROR('OEE REA'!J390*'SPEED FACTOR REA'!L35,"") -> 0 | P35: =IFERROR(N35/M35,"") | R35: =G35/O35 -> #DIV/0!
A36: =+'OEE REA'!A547 -> 388 | B36: =WEEKNUM(C36) -> 0 | C36: =+'OEE REA'!D547 -> 0 | D36: +'OEE REA'!B37 | E36: =VLOOKUP(A36,'OEE REA'!A:AO,13,FALSE) -> 816 | F36: =VLOOKUP(A36,'OEE REA'!A:AO,11,FALSE) -> 450 | G36: =IFERROR(E36/H36*60,"") -> 320 | H36: =VLOOKUP(A36,'OEE REA'!A:AO,14,FALSE) -> 153 | M36: =IFERROR(G36*L36,"") -> 0 | N36: =IFERROR(F36*L36,"") -> 0 | O36: =IFERROR('OEE REA'!J547*'SPEED FACTOR REA'!L36,"") -> 0 | P36: =IFERROR(N36/M36,"") | R36: =G36/O36 -> #DIV/0!
A37: =+'OEE REA'!A548 -> 389 | B37: =WEEKNUM(C37) -> 0 | C37: =+'OEE REA'!D548 -> 0 | D37: +'OEE REA'!B38 | E37: =VLOOKUP(A37,'OEE REA'!A:AO,13,FALSE) -> 109 | F37: =VLOOKUP(A37,'OEE REA'!A:AO,11,FALSE) -> 120 | G37: =IFERROR(E37/H37*60,"") -> 42.745098 | H37: =VLOOKUP(A37,'OEE REA'!A:AO,14,FALSE) -> 153 | M37: =IFERROR(G37*L37,"") -> 0 | N37: =IFERROR(F37*L37,"") -> 0 | O37: =IFERROR('OEE REA'!J548*'SPEED FACTOR REA'!L37,"") -> 0 | P37: =IFERROR(N37/M37,"") | R37: =G37/O37 -> #DIV/0!
A38: =+'OEE REA'!A549 -> 390 | B38: =WEEKNUM(C38) -> 0 | C38: =+'OEE REA'!D549 -> 0 | D38: +'OEE REA'!B39 | E38: =VLOOKUP(A38,'OEE REA'!A:AO,13,FALSE) -> 862 | F38: =VLOOKUP(A38,'OEE REA'!A:AO,11,FALSE) -> 450 | G38: =IFERROR(E38/H38*60,"") -> 338.03922 | H38: =VLOOKUP(A38,'OEE REA'!A:AO,14,FALSE) -> 153 | M38: =IFERROR(G38*L38,"") -> 0 | N38: =IFERROR(F38*L38,"") -> 0 | O38: =IFERROR('OEE REA'!J549*'SPEED FACTOR REA'!L38,"") -> 0 | P38: =IFERROR(N38/M38,"") | R38: =G38/O38 -> #DIV/0!
A39: =+'OEE REA'!A550 -> 391 | B39: =WEEKNUM(C39) -> 0 | C39: =+'OEE REA'!D550 -> 0 | D39: +'OEE REA'!B40 | E39: =VLOOKUP(A39,'OEE REA'!A:AO,13,FALSE) -> 281 | F39: =VLOOKUP(A39,'OEE REA'!A:AO,11,FALSE) -> 510 | G39: =IFERROR(E39/H39*60,"") -> 110.19608 | H39: =VLOOKUP(A39,'OEE REA'!A:AO,14,FALSE) -> 153 | M39: =IFERROR(G39*L39,"") -> 0 | N39: =IFERROR(F39*L39,"") -> 0 | O39: =IFERROR('OEE REA'!J550*'SPEED FACTOR REA'!L39,"") -> 0 | P39: =IFERROR(N39/M39,"") | R39: =G39/O39 -> #DIV/0!
A40: =+'OEE REA'!A551 -> 392 | B40: =WEEKNUM(C40) -> 0 | C40: =+'OEE REA'!D551 -> 0 | D40: +'OEE REA'!B41 | E40: =VLOOKUP(A40,'OEE REA'!A:AO,13,FALSE) -> 593 | F40: =VLOOKUP(A40,'OEE REA'!A:AO,11,FALSE) -> 315 | G40: =IFERROR(E40/H40*60,"") -> 232.54902 | H40: =VLOOKUP(A40,'OEE REA'!A:AO,14,FALSE) -> 153 | M40: =IFERROR(G40*L40,"") -> 0 | N40: =IFERROR(F40*L40,"") -> 0 | O40: =IFERROR('OEE REA'!J551*'SPEED FACTOR REA'!L40,"") -> 0 | P40: =IFERROR(N40/M40,"") | R40: =G40/O40 -> #DIV/0!
A41: =+'OEE REA'!A552 -> 393 | B41: =WEEKNUM(C41) -> 0 | C41: =+'OEE REA'!D552 -> 0 | D41: +'OEE REA'!B42 | E41: =VLOOKUP(A41,'OEE REA'!A:AO,13,FALSE) -> 816 | F41: =VLOOKUP(A41,'OEE REA'!A:AO,11,FALSE) -> 450 | G41: =IFERROR(E41/H41*60,"") -> 320 | H41: =VLOOKUP(A41,'OEE REA'!A:AO,14,FALSE) -> 153 | M41: =IFERROR(G41*L41,"") -> 0 | N41: =IFERROR(F41*L41,"") -> 0 | O41: =IFERROR('OEE REA'!J552*'SPEED FACTOR REA'!L41,"") -> 0 | P41: =IFERROR(N41/M41,"") | R41: =G41/O41 -> #DIV/0!
A42: =+'OEE REA'!A553 -> 394 | B42: =WEEKNUM(C42) -> 0 | C42: =+'OEE REA'!D553 -> 0 | D42: +'OEE REA'!B43 | E42: =VLOOKUP(A42,'OEE REA'!A:AO,13,FALSE) -> 1153 | F42: =VLOOKUP(A42,'OEE REA'!A:AO,11,FALSE) -> 510 | G42: =IFERROR(E42/H42*60,"") -> 452.15686 | H42: =VLOOKUP(A42,'OEE REA'!A:AO,14,FALSE) -> 153 | M42: =IFERROR(G42*L42,"") -> 0 | N42: =IFERROR(F42*L42,"") -> 0 | O42: =IFERROR('OEE REA'!J553*'SPEED FACTOR REA'!L42,"") -> 0 | P42: =IFERROR(N42/M42,"") | R42: =G42/O42 -> #DIV/0!
A43: =+'OEE REA'!A554 -> 395 | B43: =WEEKNUM(C43) -> 0 | C43: =+'OEE REA'!D554 -> 0 | D43: +'OEE REA'!B44 | E43: =VLOOKUP(A43,'OEE REA'!A:AO,13,FALSE) -> 1081 | F43: =VLOOKUP(A43,'OEE REA'!A:AO,11,FALSE) -> 435 | G43: =IFERROR(E43/H43*60,"") -> 423.92157 | H43: =VLOOKUP(A43,'OEE REA'!A:AO,14,FALSE) -> 153 | M43: =IFERROR(G43*L43,"") -> 0 | N43: =IFERROR(F43*L43,"") -> 0 | O43: =IFERROR('OEE REA'!J554*'SPEED FACTOR REA'!L43,"") -> 0 | P43: =IFERROR(N43/M43,"") | R43: =G43/O43 -> #DIV/0!
A44: =+'OEE REA'!A555 -> 396 | B44: =WEEKNUM(C44) -> 0 | C44: =+'OEE REA'!D555 -> 0 | D44: +'OEE REA'!B45 | E44: =VLOOKUP(A44,'OEE REA'!A:AO,13,FALSE) -> 1116 | F44: =VLOOKUP(A44,'OEE REA'!A:AO,11,FALSE) -> 450 | G44: =IFERROR(E44/H44*60,"") -> 437.64706 | H44: =VLOOKUP(A44,'OEE REA'!A:AO,14,FALSE) -> 153 | M44: =IFERROR(G44*L44,"") -> 0 | N44: =IFERROR(F44*L44,"") -> 0 | O44: =IFERROR('OEE REA'!J555*'SPEED FACTOR REA'!L44,"") -> 0 | P44: =IFERROR(N44/M44,"") | R44: =G44/O44 -> #DIV/0!
A45: =+'OEE REA'!A556 -> 397 | B45: =WEEKNUM(C45) -> 0 | C45: =+'OEE REA'!D556 -> 0 | D45: +'OEE REA'!B46 | E45: =VLOOKUP(A45,'OEE REA'!A:AO,13,FALSE) -> 1246 | F45: =VLOOKUP(A45,'OEE REA'!A:AO,11,FALSE) -> 510 | G45: =IFERROR(E45/H45*60,"") -> 488.62745 | H45: =VLOOKUP(A45,'OEE REA'!A:AO,14,FALSE) -> 153 | M45: =IFERROR(G45*L45,"") -> 0 | N45: =IFERROR(F45*L45,"") -> 0 | O45: =IFERROR('OEE REA'!J556*'SPEED FACTOR REA'!L45,"") -> 0 | P45: =IFERROR(N45/M45,"") | R45: =G45/O45 -> #DIV/0!
A46: =+'OEE REA'!A557 -> 398 | B46: =WEEKNUM(C46) -> 0 | C46: =+'OEE REA'!D557 -> 0 | D46: +'OEE REA'!B47 | E46: =VLOOKUP(A46,'OEE REA'!A:AO,13,FALSE) -> 1212 | F46: =VLOOKUP(A46,'OEE REA'!A:AO,11,FALSE) -> 435 | G46: =IFERROR(E46/H46*60,"") -> 475.29412 | H46: =VLOOKUP(A46,'OEE REA'!A:AO,14,FALSE) -> 153 | M46: =IFERROR(G46*L46,"") -> 0 | N46: =IFERROR(F46*L46,"") -> 0 | O46: =IFERROR('OEE REA'!J557*'SPEED FACTOR REA'!L46,"") -> 0 | P46: =IFERROR(N46/M46,"") | R46: =G46/O46 -> #DIV/0!
A47: =+'OEE REA'!A558 -> 399 | B47: =WEEKNUM(C47) -> 0 | C47: =+'OEE REA'!D558 -> 0 | D47: +'OEE REA'!B48 | E47: =VLOOKUP(A47,'OEE REA'!A:AO,13,FALSE) -> 943 | F47: =VLOOKUP(A47,'OEE REA'!A:AO,11,FALSE) -> 450 | G47: =IFERROR(E47/H47*60,"") -> 369.80392 | H47: =VLOOKUP(A47,'OEE REA'!A:AO,14,FALSE) -> 153 | M47: =IFERROR(G47*L47,"") -> 0 | N47: =IFERROR(F47*L47,"") -> 0 | O47: =IFERROR('OEE REA'!J558*'SPEED FACTOR REA'!L47,"") -> 0 | P47: =IFERROR(N47/M47,"") | R47: =G47/O47 -> #DIV/0!
... A190: =+'OEE REA'!A701 -> 0 | B190: =WEEKNUM(C190) -> 0 | C190: =+'OEE REA'!D701 -> 0 | D190: +'OEE REA'!B191 | E190: =VLOOKUP(A190,'OEE REA'!A:AO,13,FALSE) -> #N/A | F190: =VLOOKUP(A190,'OEE REA'!A:AO,11,FALSE) -> #N/A | G190: =IFERROR(E190/H190*60,"") | H190: =VLOOKUP(A190,'OEE REA'!A:AO,14,FALSE) -> #N/A | M190: =IFERROR(G190*L190,"") | N190: =IFERROR(F190*L190,"") | O190: =IFERROR('OEE REA'!J701*'SPEED FACTOR REA'!L190,"") -> 0 | P190: =IFERROR(N190/M190,"") | R190: =G190/O190 -> #VALUE!
A191: =+'OEE REA'!A702 -> 0 | B191: =WEEKNUM(C191) -> 0 | C191: =+'OEE REA'!D702 -> 0 | D191: +'OEE REA'!B192 | E191: =VLOOKUP(A191,'OEE REA'!A:AO,13,FALSE) -> #N/A | F191: =VLOOKUP(A191,'OEE REA'!A:AO,11,FALSE)/60 -> #N/A | G191: =IFERROR(E191/H191*60,"")/60 -> #VALUE! | H191: =VLOOKUP(A191,'OEE REA'!A:AO,14,FALSE) -> #N/A | M191: =IFERROR(G191*L191,"") | N191: =IFERROR(F191*L191,"") | O191: =IFERROR('OEE REA'!J702*'SPEED FACTOR REA'!L191,"") -> 0 | P191: =IFERROR(N191/M191,"") | R191: =G191/O191 -> #VALUE!
A192: =+'OEE REA'!A703 -> 0 | B192: =WEEKNUM(C192) -> 0 | C192: =+'OEE REA'!D703 -> 0 | D192: +'OEE REA'!B193 | E192: =VLOOKUP(A192,'OEE REA'!A:AO,13,FALSE) -> #N/A | F192: =VLOOKUP(A192,'OEE REA'!A:AO,11,FALSE)/60 -> #N/A | G192: =IFERROR(E192/H192*60,"")/60 -> #VALUE! | H192: =VLOOKUP(A192,'OEE REA'!A:AO,14,FALSE) -> #N/A | M192: =IFERROR(G192*L192,"") | N192: =IFERROR(F192*L192,"") | O192: =IFERROR('OEE REA'!J703*'SPEED FACTOR REA'!L192,"") -> 0 | P192: =IFERROR(N192/M192,"") | R192: =G192/O192 -> #VALUE!
A193: =+'OEE REA'!A704 -> 0 | B193: =WEEKNUM(C193) -> 0 | C193: =+'OEE REA'!D704 -> 0 | D193: +'OEE REA'!B194 | E193: =VLOOKUP(A193,'OEE REA'!A:AO,13,FALSE) -> #N/A | F193: =VLOOKUP(A193,'OEE REA'!A:AO,11,FALSE)/60 -> #N/A | G193: =IFERROR(E193/H193*60,"")/60 -> #VALUE! | H193: =VLOOKUP(A193,'OEE REA'!A:AO,14,FALSE) -> #N/A | M193: =IFERROR(G193*L193,"") | N193: =IFERROR(F193*L193,"") | O193: =IFERROR('OEE REA'!J704*'SPEED FACTOR REA'!L193,"") -> 0 | P193: =IFERROR(N193/M193,"") | R193: =G193/O193 -> #VALUE!
A194: =+'OEE REA'!A705 -> 0 | B194: =WEEKNUM(C194) -> 0 | C194: =+'OEE REA'!D705 -> 0 | D194: +'OEE REA'!B195 | E194: =VLOOKUP(A194,'OEE REA'!A:AO,13,FALSE) -> #N/A | F194: =VLOOKUP(A194,'OEE REA'!A:AO,11,FALSE)/60 -> #N/A | G194: =IFERROR(E194/H194*60,"")/60 -> #VALUE! | H194: =VLOOKUP(A194,'OEE REA'!A:AO,14,FALSE) -> #N/A | M194: =IFERROR(G194*L194,"") | N194: =IFERROR(F194*L194,"") | O194: =IFERROR('OEE REA'!J705*'SPEED FACTOR REA'!L194,"") -> 0 | P194: =IFERROR(N194/M194,"") | R194: =G194/O194 -> #VALUE!
A195: =+'OEE REA'!A706 -> 0 | B195: =WEEKNUM(C195) -> 0 | C195: =+'OEE REA'!D706 -> 0 | D195: +'OEE REA'!B196 | E195: =VLOOKUP(A195,'OEE REA'!A:AO,13,FALSE) -> #N/A | F195: =VLOOKUP(A195,'OEE REA'!A:AO,11,FALSE)/60 -> #N/A | G195: =IFERROR(E195/H195*60,"")/60 -> #VALUE! | H195: =VLOOKUP(A195,'OEE REA'!A:AO,14,FALSE) -> #N/A | M195: =IFERROR(G195*L195,"") | N195: =IFERROR(F195*L195,"") | O195: =IFERROR('OEE REA'!J706*'SPEED FACTOR REA'!L195,"") -> 0 | P195: =IFERROR(N195/M195,"") | R195: =G195/O195 -> #VALUE!
A196: =+'OEE REA'!A707 -> 0 | B196: =WEEKNUM(C196) -> 0 | C196: =+'OEE REA'!D707 -> 0 | D196: +'OEE REA'!B197 | E196: =VLOOKUP(A196,'OEE REA'!A:AO,13,FALSE) -> #N/A | F196: =VLOOKUP(A196,'OEE REA'!A:AO,11,FALSE)/60 -> #N/A | G196: =IFERROR(E196/H196*60,"")/60 -> #VALUE! | H196: =VLOOKUP(A196,'OEE REA'!A:AO,14,FALSE) -> #N/A | M196: =IFERROR(G196*L196,"") | N196: =IFERROR(F196*L196,"") | O196: =IFERROR('OEE REA'!J707*'SPEED FACTOR REA'!L196,"") -> 0 | P196: =IFERROR(N196/M196,"") | R196: =G196/O196 -> #VALUE!
...

Sheet OEE REA
A1: STD 180 pcs por hr | E1: TIEMPOS CAIDOS | H1: DISPONIBILIDAD | M1: RENDIMIENTO | Q1: CALIDAD | AO1: OEE | AP1: PPMS | BA1: SFT REA
A2: REF VLOOK UP | B2: Parte Numero | C2: TURNO | D2: FECHA | E2: LIBERACION SET UP | F2: MTTO/ING | G2: MATERIALES OTROS | H2: TIEMPO EXTRA | I2: TIEMPO DISPONIBLE | J2: TIEMPO PLANIFICADO | K2: TIEMPO OPERATIVO | L2: RESULTADO | M2: PIEZAS PRODUCIDAS | N2: ESTANDAR | O2: MIN X HORAS | P2: RESULTADO | Q2: PIEZAS BUENAS | R2: PIEZAS PRODUCIDAS | S2: 605 | T2: 610 | U2: 620 | V2: 730 | W2: 731 | X2: 740 | Y2: 750 | Z2: 810 | AA2: 915 | AB2: 940 leak test | AC2: 960 CAW | AD2: eol | AE2: Diametro no conforme | AF2: Altura no conforme | AG2: Soldadura desalineada Crank | AH2: Ajustes de Ingenieria | AI2: Ajustes de MTTO | AJ2: SCRAP | AK2: QA TOTAL | AL2: Week num | AM2: SCRAP | AN2: RESULTADO | AO2: RESULTADO | AP2: RESULTADO | AR2: SCRAP 960 | AS2: SCRAP EOL | AT2: SUB TOTAL | AU2: Liberacion | AV2: QA ( CSL1, Proceso) | AW2: Ing | AX2: TOTAL | BA2: MINUTOS TEORICOS | BB2: Numero OP | BC2: Minutos teoricos totales | BD2: Minutos de presencia totales | BE2: Minutos pagados totales | BF2: EFICIENCIA | BG2: OP1 | BH2: OP2
